Internal Server Error: /admin/wallet/activationmenu/
Traceback (most recent call last):
  File "C:\Users\Arulraj\AppData\Roaming\Python\Python313\site-packages\django\db\backends\utils.py", line 89, in _execute
    return self.cursor.execute(sql, params)
           ~~~~~~~~~~~~~~~~~~~^^^^^^^^^^^^^
  File "C:\Users\Arulraj\AppData\Roaming\Python\Python313\site-packages\django\db\backends\mysql\base.py", line 75, in execute
    return self.cursor.execute(query, args)
           ~~~~~~~~~~~~~~~~~~~^^^^^^^^^^^^^
  File "C:\Users\Arulraj\AppData\Roaming\Python\Python313\site-packages\MySQLdb\cursors.py", line 179, in execute
    res = self._query(mogrified_query)
  File "C:\Users\Arulraj\AppData\Roaming\Python\Python313\site-packages\MySQLdb\cursors.py", line 330, in _query
    db.query(q)
    ~~~~~~~~^^^
  File "C:\Users\Arulraj\AppData\Roaming\Python\Python313\site-packages\MySQLdb\connections.py", line 280, in query
    _mysql.connection.query(self, query)
    ~~~~~~~~~~~~~~~~~~~~~~~^^^^^^^^^^^^^
MySQLdb.ProgrammingError: (1146, "Table 'skyplay_api_hub2.wallet_activationmenu' doesn't exist")

The above exception was the direct cause of the following exception:

Traceback (most recent call last):
  File "C:\Users\Arulraj\AppData\Roaming\Python\Python313\site-packages\django\core\handlers\exception.py", line 55, in inner
    response = get_response(request)
  File "C:\Users\Arulraj\AppData\Roaming\Python\Python313\site-packages\django\core\handlers\base.py", line 197, in _get_response
    response = wrapped_callback(request, *callback_args, **callback_kwargs)
  File "C:\Users\Arulraj\AppData\Roaming\Python\Python313\site-packages\django\contrib\admin\options.py", line 688, in wrapper
    return self.admin_site.admin_view(view)(*args, **kwargs)
           ~~~~~~~~~~~~~~~~~~~~~~~~~~~~~~~~^^^^^^^^^^^^^^^^^
  File "C:\Users\Arulraj\AppData\Roaming\Python\Python313\site-packages\django\utils\decorators.py", line 134, in _wrapper_view
    response = view_func(request, *args, **kwargs)
  File "C:\Users\Arulraj\AppData\Roaming\Python\Python313\site-packages\django\views\decorators\cache.py", line 62, in _wrapper_view_func
    response = view_func(request, *args, **kwargs)
  File "C:\Users\Arulraj\AppData\Roaming\Python\Python313\site-packages\django\contrib\admin\sites.py", line 242, in inner
    return view(request, *args, **kwargs)
  File "C:\Users\Arulraj\AppData\Roaming\Python\Python313\site-packages\django\utils\decorators.py", line 46, in _wrapper
    return bound_method(*args, **kwargs)
  File "C:\Users\Arulraj\AppData\Roaming\Python\Python313\site-packages\django\utils\decorators.py", line 134, in _wrapper_view
    response = view_func(request, *args, **kwargs)
  File "C:\Users\Arulraj\AppData\Roaming\Python\Python313\site-packages\django\contrib\admin\options.py", line 1926, in changelist_view
    cl = self.get_changelist_instance(request)
  File "C:\Users\Arulraj\AppData\Roaming\Python\Python313\site-packages\django\contrib\admin\options.py", line 836, in get_changelist_instance
    return ChangeList(
        request,
    ...<12 lines>...
        self.search_help_text,
    )
  File "C:\Users\Arulraj\AppData\Roaming\Python\Python313\site-packages\django\contrib\admin\views\main.py", line 123, in __init__
    self.get_results(request)
    ~~~~~~~~~~~~~~~~^^^^^^^^^
  File "C:\Users\Arulraj\AppData\Roaming\Python\Python313\site-packages\django\contrib\admin\views\main.py", line 279, in get_results
    result_count = paginator.count
                   ^^^^^^^^^^^^^^^
  File "C:\Users\Arulraj\AppData\Roaming\Python\Python313\site-packages\django\utils\functional.py", line 57, in __get__
    res = instance.__dict__[self.name] = self.func(instance)
                                         ~~~~~~~~~^^^^^^^^^^
  File "C:\Users\Arulraj\AppData\Roaming\Python\Python313\site-packages\django\core\paginator.py", line 93, in count
    return c()
  File "C:\Users\Arulraj\AppData\Roaming\Python\Python313\site-packages\django\db\models\query.py", line 608, in count
    return self.query.get_count(using=self.db)
           ~~~~~~~~~~~~~~~~~~~~^^^^^^^^^^^^^^^
  File "C:\Users\Arulraj\AppData\Roaming\Python\Python313\site-packages\django\db\models\sql\query.py", line 568, in get_count
    return obj.get_aggregation(using, {"__count": Count("*")})["__count"]
           ~~~~~~~~~~~~~~~~~~~^^^^^^^^^^^^^^^^^^^^^^^^^^^^^^^^
  File "C:\Users\Arulraj\AppData\Roaming\Python\Python313\site-packages\django\db\models\sql\query.py", line 554, in get_aggregation
    result = compiler.execute_sql(SINGLE)
  File "C:\Users\Arulraj\AppData\Roaming\Python\Python313\site-packages\django\db\models\sql\compiler.py", line 1562, in execute_sql
    cursor.execute(sql, params)
    ~~~~~~~~~~~~~~^^^^^^^^^^^^^
  File "C:\Users\Arulraj\AppData\Roaming\Python\Python313\site-packages\django\db\backends\utils.py", line 102, in execute
    return super().execute(sql, params)
           ~~~~~~~~~~~~~~~^^^^^^^^^^^^^
  File "C:\Users\Arulraj\AppData\Roaming\Python\Python313\site-packages\django\db\backends\utils.py", line 67, in execute
    return self._execute_with_wrappers(
           ~~~~~~~~~~~~~~~~~~~~~~~~~~~^
        sql, params, many=False, executor=self._execute
        ^^^^^^^^^^^^^^^^^^^^^^^^^^^^^^^^^^^^^^^^^^^^^^^
    )
    ^
  File "C:\Users\Arulraj\AppData\Roaming\Python\Python313\site-packages\django\db\backends\utils.py", line 80, in _execute_with_wrappers
    return executor(sql, params, many, context)
  File "C:\Users\Arulraj\AppData\Roaming\Python\Python313\site-packages\django\db\backends\utils.py", line 84, in _execute
    with self.db.wrap_database_errors:
         ^^^^^^^^^^^^^^^^^^^^^^^^^^^^
  File "C:\Users\Arulraj\AppData\Roaming\Python\Python313\site-packages\django\db\utils.py", line 91, in __exit__
    raise dj_exc_value.with_traceback(traceback) from exc_value
  File "C:\Users\Arulraj\AppData\Roaming\Python\Python313\site-packages\django\db\backends\utils.py", line 89, in _execute
    return self.cursor.execute(sql, params)
           ~~~~~~~~~~~~~~~~~~~^^^^^^^^^^^^^
  File "C:\Users\Arulraj\AppData\Roaming\Python\Python313\site-packages\django\db\backends\mysql\base.py", line 75, in execute
    return self.cursor.execute(query, args)
           ~~~~~~~~~~~~~~~~~~~^^^^^^^^^^^^^
  File "C:\Users\Arulraj\AppData\Roaming\Python\Python313\site-packages\MySQLdb\cursors.py", line 179, in execute
    res = self._query(mogrified_query)
  File "C:\Users\Arulraj\AppData\Roaming\Python\Python313\site-packages\MySQLdb\cursors.py", line 330, in _query
    db.query(q)
    ~~~~~~~~^^^
  File "C:\Users\Arulraj\AppData\Roaming\Python\Python313\site-packages\MySQLdb\connections.py", line 280, in query
    _mysql.connection.query(self, query)
    ~~~~~~~~~~~~~~~~~~~~~~~^^^^^^^^^^^^^
django.db.utils.ProgrammingError: (1146, "Table 'skyplay_api_hub2.wallet_activationmenu' doesn't exist")
"GET /admin/wallet/activationmenu/ HTTP/1.1" 500 204747
Internal Server Error: /admin/wallet/activation/
Traceback (most recent call last):
  File "C:\Users\Arulraj\AppData\Roaming\Python\Python313\site-packages\django\db\backends\utils.py", line 89, in _execute
    return self.cursor.execute(sql, params)
           ~~~~~~~~~~~~~~~~~~~^^^^^^^^^^^^^
  File "C:\Users\Arulraj\AppData\Roaming\Python\Python313\site-packages\django\db\backends\mysql\base.py", line 75, in execute
    return self.cursor.execute(query, args)
           ~~~~~~~~~~~~~~~~~~~^^^^^^^^^^^^^
  File "C:\Users\Arulraj\AppData\Roaming\Python\Python313\site-packages\MySQLdb\cursors.py", line 179, in execute
    res = self._query(mogrified_query)
  File "C:\Users\Arulraj\AppData\Roaming\Python\Python313\site-packages\MySQLdb\cursors.py", line 330, in _query
    db.query(q)
    ~~~~~~~~^^^
  File "C:\Users\Arulraj\AppData\Roaming\Python\Python313\site-packages\MySQLdb\connections.py", line 280, in query
    _mysql.connection.query(self, query)
    ~~~~~~~~~~~~~~~~~~~~~~~^^^^^^^^^^^^^
MySQLdb.ProgrammingError: (1146, "Table 'skyplay_api_hub2.wallet_activation' doesn't exist")

The above exception was the direct cause of the following exception:

Traceback (most recent call last):
  File "C:\Users\Arulraj\AppData\Roaming\Python\Python313\site-packages\django\core\handlers\exception.py", line 55, in inner
    response = get_response(request)
  File "C:\Users\Arulraj\AppData\Roaming\Python\Python313\site-packages\django\core\handlers\base.py", line 197, in _get_response
    response = wrapped_callback(request, *callback_args, **callback_kwargs)
  File "C:\Users\Arulraj\AppData\Roaming\Python\Python313\site-packages\django\contrib\admin\options.py", line 688, in wrapper
    return self.admin_site.admin_view(view)(*args, **kwargs)
           ~~~~~~~~~~~~~~~~~~~~~~~~~~~~~~~~^^^^^^^^^^^^^^^^^
  File "C:\Users\Arulraj\AppData\Roaming\Python\Python313\site-packages\django\utils\decorators.py", line 134, in _wrapper_view
    response = view_func(request, *args, **kwargs)
  File "C:\Users\Arulraj\AppData\Roaming\Python\Python313\site-packages\django\views\decorators\cache.py", line 62, in _wrapper_view_func
    response = view_func(request, *args, **kwargs)
  File "C:\Users\Arulraj\AppData\Roaming\Python\Python313\site-packages\django\contrib\admin\sites.py", line 242, in inner
    return view(request, *args, **kwargs)
  File "C:\Users\Arulraj\AppData\Roaming\Python\Python313\site-packages\django\utils\decorators.py", line 46, in _wrapper
    return bound_method(*args, **kwargs)
  File "C:\Users\Arulraj\AppData\Roaming\Python\Python313\site-packages\django\utils\decorators.py", line 134, in _wrapper_view
    response = view_func(request, *args, **kwargs)
  File "C:\Users\Arulraj\AppData\Roaming\Python\Python313\site-packages\django\contrib\admin\options.py", line 1926, in changelist_view
    cl = self.get_changelist_instance(request)
  File "C:\Users\Arulraj\AppData\Roaming\Python\Python313\site-packages\django\contrib\admin\options.py", line 836, in get_changelist_instance
    return ChangeList(
        request,
    ...<12 lines>...
        self.search_help_text,
    )
  File "C:\Users\Arulraj\AppData\Roaming\Python\Python313\site-packages\django\contrib\admin\views\main.py", line 123, in __init__
    self.get_results(request)
    ~~~~~~~~~~~~~~~~^^^^^^^^^
  File "C:\Users\Arulraj\AppData\Roaming\Python\Python313\site-packages\django\contrib\admin\views\main.py", line 279, in get_results
    result_count = paginator.count
                   ^^^^^^^^^^^^^^^
  File "C:\Users\Arulraj\AppData\Roaming\Python\Python313\site-packages\django\utils\functional.py", line 57, in __get__
    res = instance.__dict__[self.name] = self.func(instance)
                                         ~~~~~~~~~^^^^^^^^^^
  File "C:\Users\Arulraj\AppData\Roaming\Python\Python313\site-packages\django\core\paginator.py", line 93, in count
    return c()
  File "C:\Users\Arulraj\AppData\Roaming\Python\Python313\site-packages\django\db\models\query.py", line 608, in count
    return self.query.get_count(using=self.db)
           ~~~~~~~~~~~~~~~~~~~~^^^^^^^^^^^^^^^
  File "C:\Users\Arulraj\AppData\Roaming\Python\Python313\site-packages\django\db\models\sql\query.py", line 568, in get_count
    return obj.get_aggregation(using, {"__count": Count("*")})["__count"]
           ~~~~~~~~~~~~~~~~~~~^^^^^^^^^^^^^^^^^^^^^^^^^^^^^^^^
  File "C:\Users\Arulraj\AppData\Roaming\Python\Python313\site-packages\django\db\models\sql\query.py", line 554, in get_aggregation
    result = compiler.execute_sql(SINGLE)
  File "C:\Users\Arulraj\AppData\Roaming\Python\Python313\site-packages\django\db\models\sql\compiler.py", line 1562, in execute_sql
    cursor.execute(sql, params)
    ~~~~~~~~~~~~~~^^^^^^^^^^^^^
  File "C:\Users\Arulraj\AppData\Roaming\Python\Python313\site-packages\django\db\backends\utils.py", line 102, in execute
    return super().execute(sql, params)
           ~~~~~~~~~~~~~~~^^^^^^^^^^^^^
  File "C:\Users\Arulraj\AppData\Roaming\Python\Python313\site-packages\django\db\backends\utils.py", line 67, in execute
    return self._execute_with_wrappers(
           ~~~~~~~~~~~~~~~~~~~~~~~~~~~^
        sql, params, many=False, executor=self._execute
        ^^^^^^^^^^^^^^^^^^^^^^^^^^^^^^^^^^^^^^^^^^^^^^^
    )
    ^
  File "C:\Users\Arulraj\AppData\Roaming\Python\Python313\site-packages\django\db\backends\utils.py", line 80, in _execute_with_wrappers
    return executor(sql, params, many, context)
  File "C:\Users\Arulraj\AppData\Roaming\Python\Python313\site-packages\django\db\backends\utils.py", line 84, in _execute
    with self.db.wrap_database_errors:
         ^^^^^^^^^^^^^^^^^^^^^^^^^^^^
  File "C:\Users\Arulraj\AppData\Roaming\Python\Python313\site-packages\django\db\utils.py", line 91, in __exit__
    raise dj_exc_value.with_traceback(traceback) from exc_value
  File "C:\Users\Arulraj\AppData\Roaming\Python\Python313\site-packages\django\db\backends\utils.py", line 89, in _execute
    return self.cursor.execute(sql, params)
           ~~~~~~~~~~~~~~~~~~~^^^^^^^^^^^^^
  File "C:\Users\Arulraj\AppData\Roaming\Python\Python313\site-packages\django\db\backends\mysql\base.py", line 75, in execute
    return self.cursor.execute(query, args)
           ~~~~~~~~~~~~~~~~~~~^^^^^^^^^^^^^
  File "C:\Users\Arulraj\AppData\Roaming\Python\Python313\site-packages\MySQLdb\cursors.py", line 179, in execute
    res = self._query(mogrified_query)
  File "C:\Users\Arulraj\AppData\Roaming\Python\Python313\site-packages\MySQLdb\cursors.py", line 330, in _query
    db.query(q)
    ~~~~~~~~^^^
  File "C:\Users\Arulraj\AppData\Roaming\Python\Python313\site-packages\MySQLdb\connections.py", line 280, in query
    _mysql.connection.query(self, query)
    ~~~~~~~~~~~~~~~~~~~~~~~^^^^^^^^^^^^^
django.db.utils.ProgrammingError: (1146, "Table 'skyplay_api_hub2.wallet_activation' doesn't exist")
"GET /admin/wallet/activation/ HTTP/1.1" 500 204511
Internal Server Error: /admin/subscribe/activation/
Traceback (most recent call last):
  File "C:\Users\Arulraj\AppData\Roaming\Python\Python313\site-packages\django\db\backends\utils.py", line 89, in _execute
    return self.cursor.execute(sql, params)
           ~~~~~~~~~~~~~~~~~~~^^^^^^^^^^^^^
  File "C:\Users\Arulraj\AppData\Roaming\Python\Python313\site-packages\django\db\backends\mysql\base.py", line 75, in execute
    return self.cursor.execute(query, args)
           ~~~~~~~~~~~~~~~~~~~^^^^^^^^^^^^^
  File "C:\Users\Arulraj\AppData\Roaming\Python\Python313\site-packages\MySQLdb\cursors.py", line 179, in execute
    res = self._query(mogrified_query)
  File "C:\Users\Arulraj\AppData\Roaming\Python\Python313\site-packages\MySQLdb\cursors.py", line 330, in _query
    db.query(q)
    ~~~~~~~~^^^
  File "C:\Users\Arulraj\AppData\Roaming\Python\Python313\site-packages\MySQLdb\connections.py", line 280, in query
    _mysql.connection.query(self, query)
    ~~~~~~~~~~~~~~~~~~~~~~~^^^^^^^^^^^^^
MySQLdb.OperationalError: (1054, "Unknown column 'subscribe_activation.client_id' in 'field list'")

The above exception was the direct cause of the following exception:

Traceback (most recent call last):
  File "C:\Users\Arulraj\AppData\Roaming\Python\Python313\site-packages\django\core\handlers\exception.py", line 55, in inner
    response = get_response(request)
  File "C:\Users\Arulraj\AppData\Roaming\Python\Python313\site-packages\django\core\handlers\base.py", line 197, in _get_response
    response = wrapped_callback(request, *callback_args, **callback_kwargs)
  File "C:\Users\Arulraj\AppData\Roaming\Python\Python313\site-packages\django\contrib\admin\options.py", line 688, in wrapper
    return self.admin_site.admin_view(view)(*args, **kwargs)
           ~~~~~~~~~~~~~~~~~~~~~~~~~~~~~~~~^^^^^^^^^^^^^^^^^
  File "C:\Users\Arulraj\AppData\Roaming\Python\Python313\site-packages\django\utils\decorators.py", line 134, in _wrapper_view
    response = view_func(request, *args, **kwargs)
  File "C:\Users\Arulraj\AppData\Roaming\Python\Python313\site-packages\django\views\decorators\cache.py", line 62, in _wrapper_view_func
    response = view_func(request, *args, **kwargs)
  File "C:\Users\Arulraj\AppData\Roaming\Python\Python313\site-packages\django\contrib\admin\sites.py", line 242, in inner
    return view(request, *args, **kwargs)
  File "C:\Users\Arulraj\AppData\Roaming\Python\Python313\site-packages\django\utils\decorators.py", line 46, in _wrapper
    return bound_method(*args, **kwargs)
  File "C:\Users\Arulraj\AppData\Roaming\Python\Python313\site-packages\django\utils\decorators.py", line 134, in _wrapper_view
    response = view_func(request, *args, **kwargs)
  File "C:\Users\Arulraj\AppData\Roaming\Python\Python313\site-packages\django\contrib\admin\options.py", line 2065, in changelist_view
    "selection_note": _("0 of %(cnt)s selected") % {"cnt": len(cl.result_list)},
                                                           ~~~^^^^^^^^^^^^^^^^
  File "C:\Users\Arulraj\AppData\Roaming\Python\Python313\site-packages\django\db\models\query.py", line 380, in __len__
    self._fetch_all()
    ~~~~~~~~~~~~~~~^^
  File "C:\Users\Arulraj\AppData\Roaming\Python\Python313\site-packages\django\db\models\query.py", line 1881, in _fetch_all
    self._result_cache = list(self._iterable_class(self))
                         ~~~~^^^^^^^^^^^^^^^^^^^^^^^^^^^^
  File "C:\Users\Arulraj\AppData\Roaming\Python\Python313\site-packages\django\db\models\query.py", line 91, in __iter__
    results = compiler.execute_sql(
        chunked_fetch=self.chunked_fetch, chunk_size=self.chunk_size
    )
  File "C:\Users\Arulraj\AppData\Roaming\Python\Python313\site-packages\django\db\models\sql\compiler.py", line 1562, in execute_sql
    cursor.execute(sql, params)
    ~~~~~~~~~~~~~~^^^^^^^^^^^^^
  File "C:\Users\Arulraj\AppData\Roaming\Python\Python313\site-packages\django\db\backends\utils.py", line 102, in execute
    return super().execute(sql, params)
           ~~~~~~~~~~~~~~~^^^^^^^^^^^^^
  File "C:\Users\Arulraj\AppData\Roaming\Python\Python313\site-packages\django\db\backends\utils.py", line 67, in execute
    return self._execute_with_wrappers(
           ~~~~~~~~~~~~~~~~~~~~~~~~~~~^
        sql, params, many=False, executor=self._execute
        ^^^^^^^^^^^^^^^^^^^^^^^^^^^^^^^^^^^^^^^^^^^^^^^
    )
    ^
  File "C:\Users\Arulraj\AppData\Roaming\Python\Python313\site-packages\django\db\backends\utils.py", line 80, in _execute_with_wrappers
    return executor(sql, params, many, context)
  File "C:\Users\Arulraj\AppData\Roaming\Python\Python313\site-packages\django\db\backends\utils.py", line 84, in _execute
    with self.db.wrap_database_errors:
         ^^^^^^^^^^^^^^^^^^^^^^^^^^^^
  File "C:\Users\Arulraj\AppData\Roaming\Python\Python313\site-packages\django\db\utils.py", line 91, in __exit__
    raise dj_exc_value.with_traceback(traceback) from exc_value
  File "C:\Users\Arulraj\AppData\Roaming\Python\Python313\site-packages\django\db\backends\utils.py", line 89, in _execute
    return self.cursor.execute(sql, params)
           ~~~~~~~~~~~~~~~~~~~^^^^^^^^^^^^^
  File "C:\Users\Arulraj\AppData\Roaming\Python\Python313\site-packages\django\db\backends\mysql\base.py", line 75, in execute
    return self.cursor.execute(query, args)
           ~~~~~~~~~~~~~~~~~~~^^^^^^^^^^^^^
  File "C:\Users\Arulraj\AppData\Roaming\Python\Python313\site-packages\MySQLdb\cursors.py", line 179, in execute
    res = self._query(mogrified_query)
  File "C:\Users\Arulraj\AppData\Roaming\Python\Python313\site-packages\MySQLdb\cursors.py", line 330, in _query
    db.query(q)
    ~~~~~~~~^^^
  File "C:\Users\Arulraj\AppData\Roaming\Python\Python313\site-packages\MySQLdb\connections.py", line 280, in query
    _mysql.connection.query(self, query)
    ~~~~~~~~~~~~~~~~~~~~~~~^^^^^^^^^^^^^
django.db.utils.OperationalError: (1054, "Unknown column 'subscribe_activation.client_id' in 'field list'")
"GET /admin/subscribe/activation/ HTTP/1.1" 500 184077
Internal Server Error: /admin/subscribe/activation/
Traceback (most recent call last):
  File "C:\Users\Arulraj\AppData\Roaming\Python\Python313\site-packages\django\db\backends\utils.py", line 89, in _execute
    return self.cursor.execute(sql, params)
           ~~~~~~~~~~~~~~~~~~~^^^^^^^^^^^^^
  File "C:\Users\Arulraj\AppData\Roaming\Python\Python313\site-packages\django\db\backends\mysql\base.py", line 75, in execute
    return self.cursor.execute(query, args)
           ~~~~~~~~~~~~~~~~~~~^^^^^^^^^^^^^
  File "C:\Users\Arulraj\AppData\Roaming\Python\Python313\site-packages\MySQLdb\cursors.py", line 179, in execute
    res = self._query(mogrified_query)
  File "C:\Users\Arulraj\AppData\Roaming\Python\Python313\site-packages\MySQLdb\cursors.py", line 330, in _query
    db.query(q)
    ~~~~~~~~^^^
  File "C:\Users\Arulraj\AppData\Roaming\Python\Python313\site-packages\MySQLdb\connections.py", line 280, in query
    _mysql.connection.query(self, query)
    ~~~~~~~~~~~~~~~~~~~~~~~^^^^^^^^^^^^^
MySQLdb.OperationalError: (1054, "Unknown column 'subscribe_activation.client_id' in 'field list'")

The above exception was the direct cause of the following exception:

Traceback (most recent call last):
  File "C:\Users\Arulraj\AppData\Roaming\Python\Python313\site-packages\django\core\handlers\exception.py", line 55, in inner
    response = get_response(request)
  File "C:\Users\Arulraj\AppData\Roaming\Python\Python313\site-packages\django\core\handlers\base.py", line 197, in _get_response
    response = wrapped_callback(request, *callback_args, **callback_kwargs)
  File "C:\Users\Arulraj\AppData\Roaming\Python\Python313\site-packages\django\contrib\admin\options.py", line 688, in wrapper
    return self.admin_site.admin_view(view)(*args, **kwargs)
           ~~~~~~~~~~~~~~~~~~~~~~~~~~~~~~~~^^^^^^^^^^^^^^^^^
  File "C:\Users\Arulraj\AppData\Roaming\Python\Python313\site-packages\django\utils\decorators.py", line 134, in _wrapper_view
    response = view_func(request, *args, **kwargs)
  File "C:\Users\Arulraj\AppData\Roaming\Python\Python313\site-packages\django\views\decorators\cache.py", line 62, in _wrapper_view_func
    response = view_func(request, *args, **kwargs)
  File "C:\Users\Arulraj\AppData\Roaming\Python\Python313\site-packages\django\contrib\admin\sites.py", line 242, in inner
    return view(request, *args, **kwargs)
  File "C:\Users\Arulraj\AppData\Roaming\Python\Python313\site-packages\django\utils\decorators.py", line 46, in _wrapper
    return bound_method(*args, **kwargs)
  File "C:\Users\Arulraj\AppData\Roaming\Python\Python313\site-packages\django\utils\decorators.py", line 134, in _wrapper_view
    response = view_func(request, *args, **kwargs)
  File "C:\Users\Arulraj\AppData\Roaming\Python\Python313\site-packages\django\contrib\admin\options.py", line 2065, in changelist_view
    "selection_note": _("0 of %(cnt)s selected") % {"cnt": len(cl.result_list)},
                                                           ~~~^^^^^^^^^^^^^^^^
  File "C:\Users\Arulraj\AppData\Roaming\Python\Python313\site-packages\django\db\models\query.py", line 380, in __len__
    self._fetch_all()
    ~~~~~~~~~~~~~~~^^
  File "C:\Users\Arulraj\AppData\Roaming\Python\Python313\site-packages\django\db\models\query.py", line 1881, in _fetch_all
    self._result_cache = list(self._iterable_class(self))
                         ~~~~^^^^^^^^^^^^^^^^^^^^^^^^^^^^
  File "C:\Users\Arulraj\AppData\Roaming\Python\Python313\site-packages\django\db\models\query.py", line 91, in __iter__
    results = compiler.execute_sql(
        chunked_fetch=self.chunked_fetch, chunk_size=self.chunk_size
    )
  File "C:\Users\Arulraj\AppData\Roaming\Python\Python313\site-packages\django\db\models\sql\compiler.py", line 1562, in execute_sql
    cursor.execute(sql, params)
    ~~~~~~~~~~~~~~^^^^^^^^^^^^^
  File "C:\Users\Arulraj\AppData\Roaming\Python\Python313\site-packages\django\db\backends\utils.py", line 102, in execute
    return super().execute(sql, params)
           ~~~~~~~~~~~~~~~^^^^^^^^^^^^^
  File "C:\Users\Arulraj\AppData\Roaming\Python\Python313\site-packages\django\db\backends\utils.py", line 67, in execute
    return self._execute_with_wrappers(
           ~~~~~~~~~~~~~~~~~~~~~~~~~~~^
        sql, params, many=False, executor=self._execute
        ^^^^^^^^^^^^^^^^^^^^^^^^^^^^^^^^^^^^^^^^^^^^^^^
    )
    ^
  File "C:\Users\Arulraj\AppData\Roaming\Python\Python313\site-packages\django\db\backends\utils.py", line 80, in _execute_with_wrappers
    return executor(sql, params, many, context)
  File "C:\Users\Arulraj\AppData\Roaming\Python\Python313\site-packages\django\db\backends\utils.py", line 84, in _execute
    with self.db.wrap_database_errors:
         ^^^^^^^^^^^^^^^^^^^^^^^^^^^^
  File "C:\Users\Arulraj\AppData\Roaming\Python\Python313\site-packages\django\db\utils.py", line 91, in __exit__
    raise dj_exc_value.with_traceback(traceback) from exc_value
  File "C:\Users\Arulraj\AppData\Roaming\Python\Python313\site-packages\django\db\backends\utils.py", line 89, in _execute
    return self.cursor.execute(sql, params)
           ~~~~~~~~~~~~~~~~~~~^^^^^^^^^^^^^
  File "C:\Users\Arulraj\AppData\Roaming\Python\Python313\site-packages\django\db\backends\mysql\base.py", line 75, in execute
    return self.cursor.execute(query, args)
           ~~~~~~~~~~~~~~~~~~~^^^^^^^^^^^^^
  File "C:\Users\Arulraj\AppData\Roaming\Python\Python313\site-packages\MySQLdb\cursors.py", line 179, in execute
    res = self._query(mogrified_query)
  File "C:\Users\Arulraj\AppData\Roaming\Python\Python313\site-packages\MySQLdb\cursors.py", line 330, in _query
    db.query(q)
    ~~~~~~~~^^^
  File "C:\Users\Arulraj\AppData\Roaming\Python\Python313\site-packages\MySQLdb\connections.py", line 280, in query
    _mysql.connection.query(self, query)
    ~~~~~~~~~~~~~~~~~~~~~~~^^^^^^^^^^^^^
django.db.utils.OperationalError: (1054, "Unknown column 'subscribe_activation.client_id' in 'field list'")
"GET /admin/subscribe/activation/ HTTP/1.1" 500 183949
Internal Server Error: /admin/subscribe/activation/
Traceback (most recent call last):
  File "C:\Users\Arulraj\AppData\Roaming\Python\Python313\site-packages\django\db\backends\utils.py", line 89, in _execute
    return self.cursor.execute(sql, params)
           ~~~~~~~~~~~~~~~~~~~^^^^^^^^^^^^^
  File "C:\Users\Arulraj\AppData\Roaming\Python\Python313\site-packages\django\db\backends\mysql\base.py", line 75, in execute
    return self.cursor.execute(query, args)
           ~~~~~~~~~~~~~~~~~~~^^^^^^^^^^^^^
  File "C:\Users\Arulraj\AppData\Roaming\Python\Python313\site-packages\MySQLdb\cursors.py", line 179, in execute
    res = self._query(mogrified_query)
  File "C:\Users\Arulraj\AppData\Roaming\Python\Python313\site-packages\MySQLdb\cursors.py", line 330, in _query
    db.query(q)
    ~~~~~~~~^^^
  File "C:\Users\Arulraj\AppData\Roaming\Python\Python313\site-packages\MySQLdb\connections.py", line 280, in query
    _mysql.connection.query(self, query)
    ~~~~~~~~~~~~~~~~~~~~~~~^^^^^^^^^^^^^
MySQLdb.OperationalError: (1054, "Unknown column 'subscribe_activation.client_id' in 'field list'")

The above exception was the direct cause of the following exception:

Traceback (most recent call last):
  File "C:\Users\Arulraj\AppData\Roaming\Python\Python313\site-packages\django\core\handlers\exception.py", line 55, in inner
    response = get_response(request)
  File "C:\Users\Arulraj\AppData\Roaming\Python\Python313\site-packages\django\core\handlers\base.py", line 197, in _get_response
    response = wrapped_callback(request, *callback_args, **callback_kwargs)
  File "C:\Users\Arulraj\AppData\Roaming\Python\Python313\site-packages\django\contrib\admin\options.py", line 688, in wrapper
    return self.admin_site.admin_view(view)(*args, **kwargs)
           ~~~~~~~~~~~~~~~~~~~~~~~~~~~~~~~~^^^^^^^^^^^^^^^^^
  File "C:\Users\Arulraj\AppData\Roaming\Python\Python313\site-packages\django\utils\decorators.py", line 134, in _wrapper_view
    response = view_func(request, *args, **kwargs)
  File "C:\Users\Arulraj\AppData\Roaming\Python\Python313\site-packages\django\views\decorators\cache.py", line 62, in _wrapper_view_func
    response = view_func(request, *args, **kwargs)
  File "C:\Users\Arulraj\AppData\Roaming\Python\Python313\site-packages\django\contrib\admin\sites.py", line 242, in inner
    return view(request, *args, **kwargs)
  File "C:\Users\Arulraj\AppData\Roaming\Python\Python313\site-packages\django\utils\decorators.py", line 46, in _wrapper
    return bound_method(*args, **kwargs)
  File "C:\Users\Arulraj\AppData\Roaming\Python\Python313\site-packages\django\utils\decorators.py", line 134, in _wrapper_view
    response = view_func(request, *args, **kwargs)
  File "C:\Users\Arulraj\AppData\Roaming\Python\Python313\site-packages\django\contrib\admin\options.py", line 2065, in changelist_view
    "selection_note": _("0 of %(cnt)s selected") % {"cnt": len(cl.result_list)},
                                                           ~~~^^^^^^^^^^^^^^^^
  File "C:\Users\Arulraj\AppData\Roaming\Python\Python313\site-packages\django\db\models\query.py", line 380, in __len__
    self._fetch_all()
    ~~~~~~~~~~~~~~~^^
  File "C:\Users\Arulraj\AppData\Roaming\Python\Python313\site-packages\django\db\models\query.py", line 1881, in _fetch_all
    self._result_cache = list(self._iterable_class(self))
                         ~~~~^^^^^^^^^^^^^^^^^^^^^^^^^^^^
  File "C:\Users\Arulraj\AppData\Roaming\Python\Python313\site-packages\django\db\models\query.py", line 91, in __iter__
    results = compiler.execute_sql(
        chunked_fetch=self.chunked_fetch, chunk_size=self.chunk_size
    )
  File "C:\Users\Arulraj\AppData\Roaming\Python\Python313\site-packages\django\db\models\sql\compiler.py", line 1562, in execute_sql
    cursor.execute(sql, params)
    ~~~~~~~~~~~~~~^^^^^^^^^^^^^
  File "C:\Users\Arulraj\AppData\Roaming\Python\Python313\site-packages\django\db\backends\utils.py", line 102, in execute
    return super().execute(sql, params)
           ~~~~~~~~~~~~~~~^^^^^^^^^^^^^
  File "C:\Users\Arulraj\AppData\Roaming\Python\Python313\site-packages\django\db\backends\utils.py", line 67, in execute
    return self._execute_with_wrappers(
           ~~~~~~~~~~~~~~~~~~~~~~~~~~~^
        sql, params, many=False, executor=self._execute
        ^^^^^^^^^^^^^^^^^^^^^^^^^^^^^^^^^^^^^^^^^^^^^^^
    )
    ^
  File "C:\Users\Arulraj\AppData\Roaming\Python\Python313\site-packages\django\db\backends\utils.py", line 80, in _execute_with_wrappers
    return executor(sql, params, many, context)
  File "C:\Users\Arulraj\AppData\Roaming\Python\Python313\site-packages\django\db\backends\utils.py", line 84, in _execute
    with self.db.wrap_database_errors:
         ^^^^^^^^^^^^^^^^^^^^^^^^^^^^
  File "C:\Users\Arulraj\AppData\Roaming\Python\Python313\site-packages\django\db\utils.py", line 91, in __exit__
    raise dj_exc_value.with_traceback(traceback) from exc_value
  File "C:\Users\Arulraj\AppData\Roaming\Python\Python313\site-packages\django\db\backends\utils.py", line 89, in _execute
    return self.cursor.execute(sql, params)
           ~~~~~~~~~~~~~~~~~~~^^^^^^^^^^^^^
  File "C:\Users\Arulraj\AppData\Roaming\Python\Python313\site-packages\django\db\backends\mysql\base.py", line 75, in execute
    return self.cursor.execute(query, args)
           ~~~~~~~~~~~~~~~~~~~^^^^^^^^^^^^^
  File "C:\Users\Arulraj\AppData\Roaming\Python\Python313\site-packages\MySQLdb\cursors.py", line 179, in execute
    res = self._query(mogrified_query)
  File "C:\Users\Arulraj\AppData\Roaming\Python\Python313\site-packages\MySQLdb\cursors.py", line 330, in _query
    db.query(q)
    ~~~~~~~~^^^
  File "C:\Users\Arulraj\AppData\Roaming\Python\Python313\site-packages\MySQLdb\connections.py", line 280, in query
    _mysql.connection.query(self, query)
    ~~~~~~~~~~~~~~~~~~~~~~~^^^^^^^^^^^^^
django.db.utils.OperationalError: (1054, "Unknown column 'subscribe_activation.client_id' in 'field list'")
"GET /admin/subscribe/activation/ HTTP/1.1" 500 183949
Internal Server Error: /admin/subscribe/activation/
Traceback (most recent call last):
  File "C:\Users\Arulraj\AppData\Roaming\Python\Python313\site-packages\django\db\backends\utils.py", line 89, in _execute
    return self.cursor.execute(sql, params)
           ~~~~~~~~~~~~~~~~~~~^^^^^^^^^^^^^
  File "C:\Users\Arulraj\AppData\Roaming\Python\Python313\site-packages\django\db\backends\mysql\base.py", line 75, in execute
    return self.cursor.execute(query, args)
           ~~~~~~~~~~~~~~~~~~~^^^^^^^^^^^^^
  File "C:\Users\Arulraj\AppData\Roaming\Python\Python313\site-packages\MySQLdb\cursors.py", line 179, in execute
    res = self._query(mogrified_query)
  File "C:\Users\Arulraj\AppData\Roaming\Python\Python313\site-packages\MySQLdb\cursors.py", line 330, in _query
    db.query(q)
    ~~~~~~~~^^^
  File "C:\Users\Arulraj\AppData\Roaming\Python\Python313\site-packages\MySQLdb\connections.py", line 280, in query
    _mysql.connection.query(self, query)
    ~~~~~~~~~~~~~~~~~~~~~~~^^^^^^^^^^^^^
MySQLdb.OperationalError: (1054, "Unknown column 'subscribe_activation.client_id' in 'field list'")

The above exception was the direct cause of the following exception:

Traceback (most recent call last):
  File "C:\Users\Arulraj\AppData\Roaming\Python\Python313\site-packages\django\core\handlers\exception.py", line 55, in inner
    response = get_response(request)
  File "C:\Users\Arulraj\AppData\Roaming\Python\Python313\site-packages\django\core\handlers\base.py", line 197, in _get_response
    response = wrapped_callback(request, *callback_args, **callback_kwargs)
  File "C:\Users\Arulraj\AppData\Roaming\Python\Python313\site-packages\django\contrib\admin\options.py", line 688, in wrapper
    return self.admin_site.admin_view(view)(*args, **kwargs)
           ~~~~~~~~~~~~~~~~~~~~~~~~~~~~~~~~^^^^^^^^^^^^^^^^^
  File "C:\Users\Arulraj\AppData\Roaming\Python\Python313\site-packages\django\utils\decorators.py", line 134, in _wrapper_view
    response = view_func(request, *args, **kwargs)
  File "C:\Users\Arulraj\AppData\Roaming\Python\Python313\site-packages\django\views\decorators\cache.py", line 62, in _wrapper_view_func
    response = view_func(request, *args, **kwargs)
  File "C:\Users\Arulraj\AppData\Roaming\Python\Python313\site-packages\django\contrib\admin\sites.py", line 242, in inner
    return view(request, *args, **kwargs)
  File "C:\Users\Arulraj\AppData\Roaming\Python\Python313\site-packages\django\utils\decorators.py", line 46, in _wrapper
    return bound_method(*args, **kwargs)
  File "C:\Users\Arulraj\AppData\Roaming\Python\Python313\site-packages\django\utils\decorators.py", line 134, in _wrapper_view
    response = view_func(request, *args, **kwargs)
  File "C:\Users\Arulraj\AppData\Roaming\Python\Python313\site-packages\django\contrib\admin\options.py", line 2065, in changelist_view
    "selection_note": _("0 of %(cnt)s selected") % {"cnt": len(cl.result_list)},
                                                           ~~~^^^^^^^^^^^^^^^^
  File "C:\Users\Arulraj\AppData\Roaming\Python\Python313\site-packages\django\db\models\query.py", line 380, in __len__
    self._fetch_all()
    ~~~~~~~~~~~~~~~^^
  File "C:\Users\Arulraj\AppData\Roaming\Python\Python313\site-packages\django\db\models\query.py", line 1881, in _fetch_all
    self._result_cache = list(self._iterable_class(self))
                         ~~~~^^^^^^^^^^^^^^^^^^^^^^^^^^^^
  File "C:\Users\Arulraj\AppData\Roaming\Python\Python313\site-packages\django\db\models\query.py", line 91, in __iter__
    results = compiler.execute_sql(
        chunked_fetch=self.chunked_fetch, chunk_size=self.chunk_size
    )
  File "C:\Users\Arulraj\AppData\Roaming\Python\Python313\site-packages\django\db\models\sql\compiler.py", line 1562, in execute_sql
    cursor.execute(sql, params)
    ~~~~~~~~~~~~~~^^^^^^^^^^^^^
  File "C:\Users\Arulraj\AppData\Roaming\Python\Python313\site-packages\django\db\backends\utils.py", line 102, in execute
    return super().execute(sql, params)
           ~~~~~~~~~~~~~~~^^^^^^^^^^^^^
  File "C:\Users\Arulraj\AppData\Roaming\Python\Python313\site-packages\django\db\backends\utils.py", line 67, in execute
    return self._execute_with_wrappers(
           ~~~~~~~~~~~~~~~~~~~~~~~~~~~^
        sql, params, many=False, executor=self._execute
        ^^^^^^^^^^^^^^^^^^^^^^^^^^^^^^^^^^^^^^^^^^^^^^^
    )
    ^
  File "C:\Users\Arulraj\AppData\Roaming\Python\Python313\site-packages\django\db\backends\utils.py", line 80, in _execute_with_wrappers
    return executor(sql, params, many, context)
  File "C:\Users\Arulraj\AppData\Roaming\Python\Python313\site-packages\django\db\backends\utils.py", line 84, in _execute
    with self.db.wrap_database_errors:
         ^^^^^^^^^^^^^^^^^^^^^^^^^^^^
  File "C:\Users\Arulraj\AppData\Roaming\Python\Python313\site-packages\django\db\utils.py", line 91, in __exit__
    raise dj_exc_value.with_traceback(traceback) from exc_value
  File "C:\Users\Arulraj\AppData\Roaming\Python\Python313\site-packages\django\db\backends\utils.py", line 89, in _execute
    return self.cursor.execute(sql, params)
           ~~~~~~~~~~~~~~~~~~~^^^^^^^^^^^^^
  File "C:\Users\Arulraj\AppData\Roaming\Python\Python313\site-packages\django\db\backends\mysql\base.py", line 75, in execute
    return self.cursor.execute(query, args)
           ~~~~~~~~~~~~~~~~~~~^^^^^^^^^^^^^
  File "C:\Users\Arulraj\AppData\Roaming\Python\Python313\site-packages\MySQLdb\cursors.py", line 179, in execute
    res = self._query(mogrified_query)
  File "C:\Users\Arulraj\AppData\Roaming\Python\Python313\site-packages\MySQLdb\cursors.py", line 330, in _query
    db.query(q)
    ~~~~~~~~^^^
  File "C:\Users\Arulraj\AppData\Roaming\Python\Python313\site-packages\MySQLdb\connections.py", line 280, in query
    _mysql.connection.query(self, query)
    ~~~~~~~~~~~~~~~~~~~~~~~^^^^^^^^^^^^^
django.db.utils.OperationalError: (1054, "Unknown column 'subscribe_activation.client_id' in 'field list'")
"GET /admin/subscribe/activation/ HTTP/1.1" 500 183949
Internal Server Error: /admin/subscribe/activation/
Traceback (most recent call last):
  File "C:\Users\Arulraj\AppData\Roaming\Python\Python313\site-packages\django\db\backends\utils.py", line 89, in _execute
    return self.cursor.execute(sql, params)
           ~~~~~~~~~~~~~~~~~~~^^^^^^^^^^^^^
  File "C:\Users\Arulraj\AppData\Roaming\Python\Python313\site-packages\django\db\backends\mysql\base.py", line 75, in execute
    return self.cursor.execute(query, args)
           ~~~~~~~~~~~~~~~~~~~^^^^^^^^^^^^^
  File "C:\Users\Arulraj\AppData\Roaming\Python\Python313\site-packages\MySQLdb\cursors.py", line 179, in execute
    res = self._query(mogrified_query)
  File "C:\Users\Arulraj\AppData\Roaming\Python\Python313\site-packages\MySQLdb\cursors.py", line 330, in _query
    db.query(q)
    ~~~~~~~~^^^
  File "C:\Users\Arulraj\AppData\Roaming\Python\Python313\site-packages\MySQLdb\connections.py", line 280, in query
    _mysql.connection.query(self, query)
    ~~~~~~~~~~~~~~~~~~~~~~~^^^^^^^^^^^^^
MySQLdb.OperationalError: (1054, "Unknown column 'subscribe_activation.client_id' in 'field list'")

The above exception was the direct cause of the following exception:

Traceback (most recent call last):
  File "C:\Users\Arulraj\AppData\Roaming\Python\Python313\site-packages\django\core\handlers\exception.py", line 55, in inner
    response = get_response(request)
  File "C:\Users\Arulraj\AppData\Roaming\Python\Python313\site-packages\django\core\handlers\base.py", line 197, in _get_response
    response = wrapped_callback(request, *callback_args, **callback_kwargs)
  File "C:\Users\Arulraj\AppData\Roaming\Python\Python313\site-packages\django\contrib\admin\options.py", line 688, in wrapper
    return self.admin_site.admin_view(view)(*args, **kwargs)
           ~~~~~~~~~~~~~~~~~~~~~~~~~~~~~~~~^^^^^^^^^^^^^^^^^
  File "C:\Users\Arulraj\AppData\Roaming\Python\Python313\site-packages\django\utils\decorators.py", line 134, in _wrapper_view
    response = view_func(request, *args, **kwargs)
  File "C:\Users\Arulraj\AppData\Roaming\Python\Python313\site-packages\django\views\decorators\cache.py", line 62, in _wrapper_view_func
    response = view_func(request, *args, **kwargs)
  File "C:\Users\Arulraj\AppData\Roaming\Python\Python313\site-packages\django\contrib\admin\sites.py", line 242, in inner
    return view(request, *args, **kwargs)
  File "C:\Users\Arulraj\AppData\Roaming\Python\Python313\site-packages\django\utils\decorators.py", line 46, in _wrapper
    return bound_method(*args, **kwargs)
  File "C:\Users\Arulraj\AppData\Roaming\Python\Python313\site-packages\django\utils\decorators.py", line 134, in _wrapper_view
    response = view_func(request, *args, **kwargs)
  File "C:\Users\Arulraj\AppData\Roaming\Python\Python313\site-packages\django\contrib\admin\options.py", line 2065, in changelist_view
    "selection_note": _("0 of %(cnt)s selected") % {"cnt": len(cl.result_list)},
                                                           ~~~^^^^^^^^^^^^^^^^
  File "C:\Users\Arulraj\AppData\Roaming\Python\Python313\site-packages\django\db\models\query.py", line 380, in __len__
    self._fetch_all()
    ~~~~~~~~~~~~~~~^^
  File "C:\Users\Arulraj\AppData\Roaming\Python\Python313\site-packages\django\db\models\query.py", line 1881, in _fetch_all
    self._result_cache = list(self._iterable_class(self))
                         ~~~~^^^^^^^^^^^^^^^^^^^^^^^^^^^^
  File "C:\Users\Arulraj\AppData\Roaming\Python\Python313\site-packages\django\db\models\query.py", line 91, in __iter__
    results = compiler.execute_sql(
        chunked_fetch=self.chunked_fetch, chunk_size=self.chunk_size
    )
  File "C:\Users\Arulraj\AppData\Roaming\Python\Python313\site-packages\django\db\models\sql\compiler.py", line 1562, in execute_sql
    cursor.execute(sql, params)
    ~~~~~~~~~~~~~~^^^^^^^^^^^^^
  File "C:\Users\Arulraj\AppData\Roaming\Python\Python313\site-packages\django\db\backends\utils.py", line 102, in execute
    return super().execute(sql, params)
           ~~~~~~~~~~~~~~~^^^^^^^^^^^^^
  File "C:\Users\Arulraj\AppData\Roaming\Python\Python313\site-packages\django\db\backends\utils.py", line 67, in execute
    return self._execute_with_wrappers(
           ~~~~~~~~~~~~~~~~~~~~~~~~~~~^
        sql, params, many=False, executor=self._execute
        ^^^^^^^^^^^^^^^^^^^^^^^^^^^^^^^^^^^^^^^^^^^^^^^
    )
    ^
  File "C:\Users\Arulraj\AppData\Roaming\Python\Python313\site-packages\django\db\backends\utils.py", line 80, in _execute_with_wrappers
    return executor(sql, params, many, context)
  File "C:\Users\Arulraj\AppData\Roaming\Python\Python313\site-packages\django\db\backends\utils.py", line 84, in _execute
    with self.db.wrap_database_errors:
         ^^^^^^^^^^^^^^^^^^^^^^^^^^^^
  File "C:\Users\Arulraj\AppData\Roaming\Python\Python313\site-packages\django\db\utils.py", line 91, in __exit__
    raise dj_exc_value.with_traceback(traceback) from exc_value
  File "C:\Users\Arulraj\AppData\Roaming\Python\Python313\site-packages\django\db\backends\utils.py", line 89, in _execute
    return self.cursor.execute(sql, params)
           ~~~~~~~~~~~~~~~~~~~^^^^^^^^^^^^^
  File "C:\Users\Arulraj\AppData\Roaming\Python\Python313\site-packages\django\db\backends\mysql\base.py", line 75, in execute
    return self.cursor.execute(query, args)
           ~~~~~~~~~~~~~~~~~~~^^^^^^^^^^^^^
  File "C:\Users\Arulraj\AppData\Roaming\Python\Python313\site-packages\MySQLdb\cursors.py", line 179, in execute
    res = self._query(mogrified_query)
  File "C:\Users\Arulraj\AppData\Roaming\Python\Python313\site-packages\MySQLdb\cursors.py", line 330, in _query
    db.query(q)
    ~~~~~~~~^^^
  File "C:\Users\Arulraj\AppData\Roaming\Python\Python313\site-packages\MySQLdb\connections.py", line 280, in query
    _mysql.connection.query(self, query)
    ~~~~~~~~~~~~~~~~~~~~~~~^^^^^^^^^^^^^
django.db.utils.OperationalError: (1054, "Unknown column 'subscribe_activation.client_id' in 'field list'")
"GET /admin/subscribe/activation/ HTTP/1.1" 500 183812
Internal Server Error: /admin/subscribe/activation/
Traceback (most recent call last):
  File "C:\Users\Arulraj\AppData\Roaming\Python\Python313\site-packages\django\db\backends\utils.py", line 89, in _execute
    return self.cursor.execute(sql, params)
           ~~~~~~~~~~~~~~~~~~~^^^^^^^^^^^^^
  File "C:\Users\Arulraj\AppData\Roaming\Python\Python313\site-packages\django\db\backends\mysql\base.py", line 75, in execute
    return self.cursor.execute(query, args)
           ~~~~~~~~~~~~~~~~~~~^^^^^^^^^^^^^
  File "C:\Users\Arulraj\AppData\Roaming\Python\Python313\site-packages\MySQLdb\cursors.py", line 179, in execute
    res = self._query(mogrified_query)
  File "C:\Users\Arulraj\AppData\Roaming\Python\Python313\site-packages\MySQLdb\cursors.py", line 330, in _query
    db.query(q)
    ~~~~~~~~^^^
  File "C:\Users\Arulraj\AppData\Roaming\Python\Python313\site-packages\MySQLdb\connections.py", line 280, in query
    _mysql.connection.query(self, query)
    ~~~~~~~~~~~~~~~~~~~~~~~^^^^^^^^^^^^^
MySQLdb.OperationalError: (1054, "Unknown column 'subscribe_activation.client_id' in 'field list'")

The above exception was the direct cause of the following exception:

Traceback (most recent call last):
  File "C:\Users\Arulraj\AppData\Roaming\Python\Python313\site-packages\django\core\handlers\exception.py", line 55, in inner
    response = get_response(request)
  File "C:\Users\Arulraj\AppData\Roaming\Python\Python313\site-packages\django\core\handlers\base.py", line 197, in _get_response
    response = wrapped_callback(request, *callback_args, **callback_kwargs)
  File "C:\Users\Arulraj\AppData\Roaming\Python\Python313\site-packages\django\contrib\admin\options.py", line 688, in wrapper
    return self.admin_site.admin_view(view)(*args, **kwargs)
           ~~~~~~~~~~~~~~~~~~~~~~~~~~~~~~~~^^^^^^^^^^^^^^^^^
  File "C:\Users\Arulraj\AppData\Roaming\Python\Python313\site-packages\django\utils\decorators.py", line 134, in _wrapper_view
    response = view_func(request, *args, **kwargs)
  File "C:\Users\Arulraj\AppData\Roaming\Python\Python313\site-packages\django\views\decorators\cache.py", line 62, in _wrapper_view_func
    response = view_func(request, *args, **kwargs)
  File "C:\Users\Arulraj\AppData\Roaming\Python\Python313\site-packages\django\contrib\admin\sites.py", line 242, in inner
    return view(request, *args, **kwargs)
  File "C:\Users\Arulraj\AppData\Roaming\Python\Python313\site-packages\django\utils\decorators.py", line 46, in _wrapper
    return bound_method(*args, **kwargs)
  File "C:\Users\Arulraj\AppData\Roaming\Python\Python313\site-packages\django\utils\decorators.py", line 134, in _wrapper_view
    response = view_func(request, *args, **kwargs)
  File "C:\Users\Arulraj\AppData\Roaming\Python\Python313\site-packages\django\contrib\admin\options.py", line 2065, in changelist_view
    "selection_note": _("0 of %(cnt)s selected") % {"cnt": len(cl.result_list)},
                                                           ~~~^^^^^^^^^^^^^^^^
  File "C:\Users\Arulraj\AppData\Roaming\Python\Python313\site-packages\django\db\models\query.py", line 380, in __len__
    self._fetch_all()
    ~~~~~~~~~~~~~~~^^
  File "C:\Users\Arulraj\AppData\Roaming\Python\Python313\site-packages\django\db\models\query.py", line 1881, in _fetch_all
    self._result_cache = list(self._iterable_class(self))
                         ~~~~^^^^^^^^^^^^^^^^^^^^^^^^^^^^
  File "C:\Users\Arulraj\AppData\Roaming\Python\Python313\site-packages\django\db\models\query.py", line 91, in __iter__
    results = compiler.execute_sql(
        chunked_fetch=self.chunked_fetch, chunk_size=self.chunk_size
    )
  File "C:\Users\Arulraj\AppData\Roaming\Python\Python313\site-packages\django\db\models\sql\compiler.py", line 1562, in execute_sql
    cursor.execute(sql, params)
    ~~~~~~~~~~~~~~^^^^^^^^^^^^^
  File "C:\Users\Arulraj\AppData\Roaming\Python\Python313\site-packages\django\db\backends\utils.py", line 102, in execute
    return super().execute(sql, params)
           ~~~~~~~~~~~~~~~^^^^^^^^^^^^^
  File "C:\Users\Arulraj\AppData\Roaming\Python\Python313\site-packages\django\db\backends\utils.py", line 67, in execute
    return self._execute_with_wrappers(
           ~~~~~~~~~~~~~~~~~~~~~~~~~~~^
        sql, params, many=False, executor=self._execute
        ^^^^^^^^^^^^^^^^^^^^^^^^^^^^^^^^^^^^^^^^^^^^^^^
    )
    ^
  File "C:\Users\Arulraj\AppData\Roaming\Python\Python313\site-packages\django\db\backends\utils.py", line 80, in _execute_with_wrappers
    return executor(sql, params, many, context)
  File "C:\Users\Arulraj\AppData\Roaming\Python\Python313\site-packages\django\db\backends\utils.py", line 84, in _execute
    with self.db.wrap_database_errors:
         ^^^^^^^^^^^^^^^^^^^^^^^^^^^^
  File "C:\Users\Arulraj\AppData\Roaming\Python\Python313\site-packages\django\db\utils.py", line 91, in __exit__
    raise dj_exc_value.with_traceback(traceback) from exc_value
  File "C:\Users\Arulraj\AppData\Roaming\Python\Python313\site-packages\django\db\backends\utils.py", line 89, in _execute
    return self.cursor.execute(sql, params)
           ~~~~~~~~~~~~~~~~~~~^^^^^^^^^^^^^
  File "C:\Users\Arulraj\AppData\Roaming\Python\Python313\site-packages\django\db\backends\mysql\base.py", line 75, in execute
    return self.cursor.execute(query, args)
           ~~~~~~~~~~~~~~~~~~~^^^^^^^^^^^^^
  File "C:\Users\Arulraj\AppData\Roaming\Python\Python313\site-packages\MySQLdb\cursors.py", line 179, in execute
    res = self._query(mogrified_query)
  File "C:\Users\Arulraj\AppData\Roaming\Python\Python313\site-packages\MySQLdb\cursors.py", line 330, in _query
    db.query(q)
    ~~~~~~~~^^^
  File "C:\Users\Arulraj\AppData\Roaming\Python\Python313\site-packages\MySQLdb\connections.py", line 280, in query
    _mysql.connection.query(self, query)
    ~~~~~~~~~~~~~~~~~~~~~~~^^^^^^^^^^^^^
django.db.utils.OperationalError: (1054, "Unknown column 'subscribe_activation.client_id' in 'field list'")
"GET /admin/subscribe/activation/ HTTP/1.1" 500 183949
Internal Server Error: /admin/subscribe/activation/
Traceback (most recent call last):
  File "C:\Users\Arulraj\AppData\Roaming\Python\Python313\site-packages\django\db\backends\utils.py", line 89, in _execute
    return self.cursor.execute(sql, params)
           ~~~~~~~~~~~~~~~~~~~^^^^^^^^^^^^^
  File "C:\Users\Arulraj\AppData\Roaming\Python\Python313\site-packages\django\db\backends\mysql\base.py", line 75, in execute
    return self.cursor.execute(query, args)
           ~~~~~~~~~~~~~~~~~~~^^^^^^^^^^^^^
  File "C:\Users\Arulraj\AppData\Roaming\Python\Python313\site-packages\MySQLdb\cursors.py", line 179, in execute
    res = self._query(mogrified_query)
  File "C:\Users\Arulraj\AppData\Roaming\Python\Python313\site-packages\MySQLdb\cursors.py", line 330, in _query
    db.query(q)
    ~~~~~~~~^^^
  File "C:\Users\Arulraj\AppData\Roaming\Python\Python313\site-packages\MySQLdb\connections.py", line 280, in query
    _mysql.connection.query(self, query)
    ~~~~~~~~~~~~~~~~~~~~~~~^^^^^^^^^^^^^
MySQLdb.OperationalError: (1054, "Unknown column 'subscribe_activation.client_id' in 'field list'")

The above exception was the direct cause of the following exception:

Traceback (most recent call last):
  File "C:\Users\Arulraj\AppData\Roaming\Python\Python313\site-packages\django\core\handlers\exception.py", line 55, in inner
    response = get_response(request)
  File "C:\Users\Arulraj\AppData\Roaming\Python\Python313\site-packages\django\core\handlers\base.py", line 197, in _get_response
    response = wrapped_callback(request, *callback_args, **callback_kwargs)
  File "C:\Users\Arulraj\AppData\Roaming\Python\Python313\site-packages\django\contrib\admin\options.py", line 688, in wrapper
    return self.admin_site.admin_view(view)(*args, **kwargs)
           ~~~~~~~~~~~~~~~~~~~~~~~~~~~~~~~~^^^^^^^^^^^^^^^^^
  File "C:\Users\Arulraj\AppData\Roaming\Python\Python313\site-packages\django\utils\decorators.py", line 134, in _wrapper_view
    response = view_func(request, *args, **kwargs)
  File "C:\Users\Arulraj\AppData\Roaming\Python\Python313\site-packages\django\views\decorators\cache.py", line 62, in _wrapper_view_func
    response = view_func(request, *args, **kwargs)
  File "C:\Users\Arulraj\AppData\Roaming\Python\Python313\site-packages\django\contrib\admin\sites.py", line 242, in inner
    return view(request, *args, **kwargs)
  File "C:\Users\Arulraj\AppData\Roaming\Python\Python313\site-packages\django\utils\decorators.py", line 46, in _wrapper
    return bound_method(*args, **kwargs)
  File "C:\Users\Arulraj\AppData\Roaming\Python\Python313\site-packages\django\utils\decorators.py", line 134, in _wrapper_view
    response = view_func(request, *args, **kwargs)
  File "C:\Users\Arulraj\AppData\Roaming\Python\Python313\site-packages\django\contrib\admin\options.py", line 2065, in changelist_view
    "selection_note": _("0 of %(cnt)s selected") % {"cnt": len(cl.result_list)},
                                                           ~~~^^^^^^^^^^^^^^^^
  File "C:\Users\Arulraj\AppData\Roaming\Python\Python313\site-packages\django\db\models\query.py", line 380, in __len__
    self._fetch_all()
    ~~~~~~~~~~~~~~~^^
  File "C:\Users\Arulraj\AppData\Roaming\Python\Python313\site-packages\django\db\models\query.py", line 1881, in _fetch_all
    self._result_cache = list(self._iterable_class(self))
                         ~~~~^^^^^^^^^^^^^^^^^^^^^^^^^^^^
  File "C:\Users\Arulraj\AppData\Roaming\Python\Python313\site-packages\django\db\models\query.py", line 91, in __iter__
    results = compiler.execute_sql(
        chunked_fetch=self.chunked_fetch, chunk_size=self.chunk_size
    )
  File "C:\Users\Arulraj\AppData\Roaming\Python\Python313\site-packages\django\db\models\sql\compiler.py", line 1562, in execute_sql
    cursor.execute(sql, params)
    ~~~~~~~~~~~~~~^^^^^^^^^^^^^
  File "C:\Users\Arulraj\AppData\Roaming\Python\Python313\site-packages\django\db\backends\utils.py", line 102, in execute
    return super().execute(sql, params)
           ~~~~~~~~~~~~~~~^^^^^^^^^^^^^
  File "C:\Users\Arulraj\AppData\Roaming\Python\Python313\site-packages\django\db\backends\utils.py", line 67, in execute
    return self._execute_with_wrappers(
           ~~~~~~~~~~~~~~~~~~~~~~~~~~~^
        sql, params, many=False, executor=self._execute
        ^^^^^^^^^^^^^^^^^^^^^^^^^^^^^^^^^^^^^^^^^^^^^^^
    )
    ^
  File "C:\Users\Arulraj\AppData\Roaming\Python\Python313\site-packages\django\db\backends\utils.py", line 80, in _execute_with_wrappers
    return executor(sql, params, many, context)
  File "C:\Users\Arulraj\AppData\Roaming\Python\Python313\site-packages\django\db\backends\utils.py", line 84, in _execute
    with self.db.wrap_database_errors:
         ^^^^^^^^^^^^^^^^^^^^^^^^^^^^
  File "C:\Users\Arulraj\AppData\Roaming\Python\Python313\site-packages\django\db\utils.py", line 91, in __exit__
    raise dj_exc_value.with_traceback(traceback) from exc_value
  File "C:\Users\Arulraj\AppData\Roaming\Python\Python313\site-packages\django\db\backends\utils.py", line 89, in _execute
    return self.cursor.execute(sql, params)
           ~~~~~~~~~~~~~~~~~~~^^^^^^^^^^^^^
  File "C:\Users\Arulraj\AppData\Roaming\Python\Python313\site-packages\django\db\backends\mysql\base.py", line 75, in execute
    return self.cursor.execute(query, args)
           ~~~~~~~~~~~~~~~~~~~^^^^^^^^^^^^^
  File "C:\Users\Arulraj\AppData\Roaming\Python\Python313\site-packages\MySQLdb\cursors.py", line 179, in execute
    res = self._query(mogrified_query)
  File "C:\Users\Arulraj\AppData\Roaming\Python\Python313\site-packages\MySQLdb\cursors.py", line 330, in _query
    db.query(q)
    ~~~~~~~~^^^
  File "C:\Users\Arulraj\AppData\Roaming\Python\Python313\site-packages\MySQLdb\connections.py", line 280, in query
    _mysql.connection.query(self, query)
    ~~~~~~~~~~~~~~~~~~~~~~~^^^^^^^^^^^^^
django.db.utils.OperationalError: (1054, "Unknown column 'subscribe_activation.client_id' in 'field list'")
"GET /admin/subscribe/activation/ HTTP/1.1" 500 183812
Internal Server Error: /admin/subscribe/activation/
Traceback (most recent call last):
  File "C:\Users\Arulraj\AppData\Roaming\Python\Python313\site-packages\django\db\backends\utils.py", line 89, in _execute
    return self.cursor.execute(sql, params)
           ~~~~~~~~~~~~~~~~~~~^^^^^^^^^^^^^
  File "C:\Users\Arulraj\AppData\Roaming\Python\Python313\site-packages\django\db\backends\mysql\base.py", line 75, in execute
    return self.cursor.execute(query, args)
           ~~~~~~~~~~~~~~~~~~~^^^^^^^^^^^^^
  File "C:\Users\Arulraj\AppData\Roaming\Python\Python313\site-packages\MySQLdb\cursors.py", line 179, in execute
    res = self._query(mogrified_query)
  File "C:\Users\Arulraj\AppData\Roaming\Python\Python313\site-packages\MySQLdb\cursors.py", line 330, in _query
    db.query(q)
    ~~~~~~~~^^^
  File "C:\Users\Arulraj\AppData\Roaming\Python\Python313\site-packages\MySQLdb\connections.py", line 280, in query
    _mysql.connection.query(self, query)
    ~~~~~~~~~~~~~~~~~~~~~~~^^^^^^^^^^^^^
MySQLdb.OperationalError: (1054, "Unknown column 'subscribe_activation.client_id' in 'field list'")

The above exception was the direct cause of the following exception:

Traceback (most recent call last):
  File "C:\Users\Arulraj\AppData\Roaming\Python\Python313\site-packages\django\core\handlers\exception.py", line 55, in inner
    response = get_response(request)
  File "C:\Users\Arulraj\AppData\Roaming\Python\Python313\site-packages\django\core\handlers\base.py", line 197, in _get_response
    response = wrapped_callback(request, *callback_args, **callback_kwargs)
  File "C:\Users\Arulraj\AppData\Roaming\Python\Python313\site-packages\django\contrib\admin\options.py", line 688, in wrapper
    return self.admin_site.admin_view(view)(*args, **kwargs)
           ~~~~~~~~~~~~~~~~~~~~~~~~~~~~~~~~^^^^^^^^^^^^^^^^^
  File "C:\Users\Arulraj\AppData\Roaming\Python\Python313\site-packages\django\utils\decorators.py", line 134, in _wrapper_view
    response = view_func(request, *args, **kwargs)
  File "C:\Users\Arulraj\AppData\Roaming\Python\Python313\site-packages\django\views\decorators\cache.py", line 62, in _wrapper_view_func
    response = view_func(request, *args, **kwargs)
  File "C:\Users\Arulraj\AppData\Roaming\Python\Python313\site-packages\django\contrib\admin\sites.py", line 242, in inner
    return view(request, *args, **kwargs)
  File "C:\Users\Arulraj\AppData\Roaming\Python\Python313\site-packages\django\utils\decorators.py", line 46, in _wrapper
    return bound_method(*args, **kwargs)
  File "C:\Users\Arulraj\AppData\Roaming\Python\Python313\site-packages\django\utils\decorators.py", line 134, in _wrapper_view
    response = view_func(request, *args, **kwargs)
  File "C:\Users\Arulraj\AppData\Roaming\Python\Python313\site-packages\django\contrib\admin\options.py", line 2065, in changelist_view
    "selection_note": _("0 of %(cnt)s selected") % {"cnt": len(cl.result_list)},
                                                           ~~~^^^^^^^^^^^^^^^^
  File "C:\Users\Arulraj\AppData\Roaming\Python\Python313\site-packages\django\db\models\query.py", line 380, in __len__
    self._fetch_all()
    ~~~~~~~~~~~~~~~^^
  File "C:\Users\Arulraj\AppData\Roaming\Python\Python313\site-packages\django\db\models\query.py", line 1881, in _fetch_all
    self._result_cache = list(self._iterable_class(self))
                         ~~~~^^^^^^^^^^^^^^^^^^^^^^^^^^^^
  File "C:\Users\Arulraj\AppData\Roaming\Python\Python313\site-packages\django\db\models\query.py", line 91, in __iter__
    results = compiler.execute_sql(
        chunked_fetch=self.chunked_fetch, chunk_size=self.chunk_size
    )
  File "C:\Users\Arulraj\AppData\Roaming\Python\Python313\site-packages\django\db\models\sql\compiler.py", line 1562, in execute_sql
    cursor.execute(sql, params)
    ~~~~~~~~~~~~~~^^^^^^^^^^^^^
  File "C:\Users\Arulraj\AppData\Roaming\Python\Python313\site-packages\django\db\backends\utils.py", line 102, in execute
    return super().execute(sql, params)
           ~~~~~~~~~~~~~~~^^^^^^^^^^^^^
  File "C:\Users\Arulraj\AppData\Roaming\Python\Python313\site-packages\django\db\backends\utils.py", line 67, in execute
    return self._execute_with_wrappers(
           ~~~~~~~~~~~~~~~~~~~~~~~~~~~^
        sql, params, many=False, executor=self._execute
        ^^^^^^^^^^^^^^^^^^^^^^^^^^^^^^^^^^^^^^^^^^^^^^^
    )
    ^
  File "C:\Users\Arulraj\AppData\Roaming\Python\Python313\site-packages\django\db\backends\utils.py", line 80, in _execute_with_wrappers
    return executor(sql, params, many, context)
  File "C:\Users\Arulraj\AppData\Roaming\Python\Python313\site-packages\django\db\backends\utils.py", line 84, in _execute
    with self.db.wrap_database_errors:
         ^^^^^^^^^^^^^^^^^^^^^^^^^^^^
  File "C:\Users\Arulraj\AppData\Roaming\Python\Python313\site-packages\django\db\utils.py", line 91, in __exit__
    raise dj_exc_value.with_traceback(traceback) from exc_value
  File "C:\Users\Arulraj\AppData\Roaming\Python\Python313\site-packages\django\db\backends\utils.py", line 89, in _execute
    return self.cursor.execute(sql, params)
           ~~~~~~~~~~~~~~~~~~~^^^^^^^^^^^^^
  File "C:\Users\Arulraj\AppData\Roaming\Python\Python313\site-packages\django\db\backends\mysql\base.py", line 75, in execute
    return self.cursor.execute(query, args)
           ~~~~~~~~~~~~~~~~~~~^^^^^^^^^^^^^
  File "C:\Users\Arulraj\AppData\Roaming\Python\Python313\site-packages\MySQLdb\cursors.py", line 179, in execute
    res = self._query(mogrified_query)
  File "C:\Users\Arulraj\AppData\Roaming\Python\Python313\site-packages\MySQLdb\cursors.py", line 330, in _query
    db.query(q)
    ~~~~~~~~^^^
  File "C:\Users\Arulraj\AppData\Roaming\Python\Python313\site-packages\MySQLdb\connections.py", line 280, in query
    _mysql.connection.query(self, query)
    ~~~~~~~~~~~~~~~~~~~~~~~^^^^^^^^^^^^^
django.db.utils.OperationalError: (1054, "Unknown column 'subscribe_activation.client_id' in 'field list'")
"GET /admin/subscribe/activation/ HTTP/1.1" 500 183807
Internal Server Error: /admin/subscribe/activation/
Traceback (most recent call last):
  File "C:\Users\Arulraj\AppData\Roaming\Python\Python313\site-packages\django\db\backends\utils.py", line 89, in _execute
    return self.cursor.execute(sql, params)
           ~~~~~~~~~~~~~~~~~~~^^^^^^^^^^^^^
  File "C:\Users\Arulraj\AppData\Roaming\Python\Python313\site-packages\django\db\backends\mysql\base.py", line 75, in execute
    return self.cursor.execute(query, args)
           ~~~~~~~~~~~~~~~~~~~^^^^^^^^^^^^^
  File "C:\Users\Arulraj\AppData\Roaming\Python\Python313\site-packages\MySQLdb\cursors.py", line 179, in execute
    res = self._query(mogrified_query)
  File "C:\Users\Arulraj\AppData\Roaming\Python\Python313\site-packages\MySQLdb\cursors.py", line 330, in _query
    db.query(q)
    ~~~~~~~~^^^
  File "C:\Users\Arulraj\AppData\Roaming\Python\Python313\site-packages\MySQLdb\connections.py", line 280, in query
    _mysql.connection.query(self, query)
    ~~~~~~~~~~~~~~~~~~~~~~~^^^^^^^^^^^^^
MySQLdb.ProgrammingError: (1146, "Table 'skyplay_api_hub2.subscribe_activation' doesn't exist")

The above exception was the direct cause of the following exception:

Traceback (most recent call last):
  File "C:\Users\Arulraj\AppData\Roaming\Python\Python313\site-packages\django\core\handlers\exception.py", line 55, in inner
    response = get_response(request)
  File "C:\Users\Arulraj\AppData\Roaming\Python\Python313\site-packages\django\core\handlers\base.py", line 197, in _get_response
    response = wrapped_callback(request, *callback_args, **callback_kwargs)
  File "C:\Users\Arulraj\AppData\Roaming\Python\Python313\site-packages\django\contrib\admin\options.py", line 688, in wrapper
    return self.admin_site.admin_view(view)(*args, **kwargs)
           ~~~~~~~~~~~~~~~~~~~~~~~~~~~~~~~~^^^^^^^^^^^^^^^^^
  File "C:\Users\Arulraj\AppData\Roaming\Python\Python313\site-packages\django\utils\decorators.py", line 134, in _wrapper_view
    response = view_func(request, *args, **kwargs)
  File "C:\Users\Arulraj\AppData\Roaming\Python\Python313\site-packages\django\views\decorators\cache.py", line 62, in _wrapper_view_func
    response = view_func(request, *args, **kwargs)
  File "C:\Users\Arulraj\AppData\Roaming\Python\Python313\site-packages\django\contrib\admin\sites.py", line 242, in inner
    return view(request, *args, **kwargs)
  File "C:\Users\Arulraj\AppData\Roaming\Python\Python313\site-packages\django\utils\decorators.py", line 46, in _wrapper
    return bound_method(*args, **kwargs)
  File "C:\Users\Arulraj\AppData\Roaming\Python\Python313\site-packages\django\utils\decorators.py", line 134, in _wrapper_view
    response = view_func(request, *args, **kwargs)
  File "C:\Users\Arulraj\AppData\Roaming\Python\Python313\site-packages\django\contrib\admin\options.py", line 1926, in changelist_view
    cl = self.get_changelist_instance(request)
  File "C:\Users\Arulraj\AppData\Roaming\Python\Python313\site-packages\django\contrib\admin\options.py", line 836, in get_changelist_instance
    return ChangeList(
        request,
    ...<12 lines>...
        self.search_help_text,
    )
  File "C:\Users\Arulraj\AppData\Roaming\Python\Python313\site-packages\django\contrib\admin\views\main.py", line 123, in __init__
    self.get_results(request)
    ~~~~~~~~~~~~~~~~^^^^^^^^^
  File "C:\Users\Arulraj\AppData\Roaming\Python\Python313\site-packages\django\contrib\admin\views\main.py", line 279, in get_results
    result_count = paginator.count
                   ^^^^^^^^^^^^^^^
  File "C:\Users\Arulraj\AppData\Roaming\Python\Python313\site-packages\django\utils\functional.py", line 57, in __get__
    res = instance.__dict__[self.name] = self.func(instance)
                                         ~~~~~~~~~^^^^^^^^^^
  File "C:\Users\Arulraj\AppData\Roaming\Python\Python313\site-packages\django\core\paginator.py", line 93, in count
    return c()
  File "C:\Users\Arulraj\AppData\Roaming\Python\Python313\site-packages\django\db\models\query.py", line 608, in count
    return self.query.get_count(using=self.db)
           ~~~~~~~~~~~~~~~~~~~~^^^^^^^^^^^^^^^
  File "C:\Users\Arulraj\AppData\Roaming\Python\Python313\site-packages\django\db\models\sql\query.py", line 568, in get_count
    return obj.get_aggregation(using, {"__count": Count("*")})["__count"]
           ~~~~~~~~~~~~~~~~~~~^^^^^^^^^^^^^^^^^^^^^^^^^^^^^^^^
  File "C:\Users\Arulraj\AppData\Roaming\Python\Python313\site-packages\django\db\models\sql\query.py", line 554, in get_aggregation
    result = compiler.execute_sql(SINGLE)
  File "C:\Users\Arulraj\AppData\Roaming\Python\Python313\site-packages\django\db\models\sql\compiler.py", line 1562, in execute_sql
    cursor.execute(sql, params)
    ~~~~~~~~~~~~~~^^^^^^^^^^^^^
  File "C:\Users\Arulraj\AppData\Roaming\Python\Python313\site-packages\django\db\backends\utils.py", line 102, in execute
    return super().execute(sql, params)
           ~~~~~~~~~~~~~~~^^^^^^^^^^^^^
  File "C:\Users\Arulraj\AppData\Roaming\Python\Python313\site-packages\django\db\backends\utils.py", line 67, in execute
    return self._execute_with_wrappers(
           ~~~~~~~~~~~~~~~~~~~~~~~~~~~^
        sql, params, many=False, executor=self._execute
        ^^^^^^^^^^^^^^^^^^^^^^^^^^^^^^^^^^^^^^^^^^^^^^^
    )
    ^
  File "C:\Users\Arulraj\AppData\Roaming\Python\Python313\site-packages\django\db\backends\utils.py", line 80, in _execute_with_wrappers
    return executor(sql, params, many, context)
  File "C:\Users\Arulraj\AppData\Roaming\Python\Python313\site-packages\django\db\backends\utils.py", line 84, in _execute
    with self.db.wrap_database_errors:
         ^^^^^^^^^^^^^^^^^^^^^^^^^^^^
  File "C:\Users\Arulraj\AppData\Roaming\Python\Python313\site-packages\django\db\utils.py", line 91, in __exit__
    raise dj_exc_value.with_traceback(traceback) from exc_value
  File "C:\Users\Arulraj\AppData\Roaming\Python\Python313\site-packages\django\db\backends\utils.py", line 89, in _execute
    return self.cursor.execute(sql, params)
           ~~~~~~~~~~~~~~~~~~~^^^^^^^^^^^^^
  File "C:\Users\Arulraj\AppData\Roaming\Python\Python313\site-packages\django\db\backends\mysql\base.py", line 75, in execute
    return self.cursor.execute(query, args)
           ~~~~~~~~~~~~~~~~~~~^^^^^^^^^^^^^
  File "C:\Users\Arulraj\AppData\Roaming\Python\Python313\site-packages\MySQLdb\cursors.py", line 179, in execute
    res = self._query(mogrified_query)
  File "C:\Users\Arulraj\AppData\Roaming\Python\Python313\site-packages\MySQLdb\cursors.py", line 330, in _query
    db.query(q)
    ~~~~~~~~^^^
  File "C:\Users\Arulraj\AppData\Roaming\Python\Python313\site-packages\MySQLdb\connections.py", line 280, in query
    _mysql.connection.query(self, query)
    ~~~~~~~~~~~~~~~~~~~~~~~^^^^^^^^^^^^^
django.db.utils.ProgrammingError: (1146, "Table 'skyplay_api_hub2.subscribe_activation' doesn't exist")
"GET /admin/subscribe/activation/ HTTP/1.1" 500 205097
Internal Server Error: /admin/subscribe/activation/
Traceback (most recent call last):
  File "C:\Users\Arulraj\AppData\Roaming\Python\Python313\site-packages\django\db\backends\utils.py", line 89, in _execute
    return self.cursor.execute(sql, params)
           ~~~~~~~~~~~~~~~~~~~^^^^^^^^^^^^^
  File "C:\Users\Arulraj\AppData\Roaming\Python\Python313\site-packages\django\db\backends\mysql\base.py", line 75, in execute
    return self.cursor.execute(query, args)
           ~~~~~~~~~~~~~~~~~~~^^^^^^^^^^^^^
  File "C:\Users\Arulraj\AppData\Roaming\Python\Python313\site-packages\MySQLdb\cursors.py", line 179, in execute
    res = self._query(mogrified_query)
  File "C:\Users\Arulraj\AppData\Roaming\Python\Python313\site-packages\MySQLdb\cursors.py", line 330, in _query
    db.query(q)
    ~~~~~~~~^^^
  File "C:\Users\Arulraj\AppData\Roaming\Python\Python313\site-packages\MySQLdb\connections.py", line 280, in query
    _mysql.connection.query(self, query)
    ~~~~~~~~~~~~~~~~~~~~~~~^^^^^^^^^^^^^
MySQLdb.ProgrammingError: (1146, "Table 'skyplay_api_hub2.subscribe_activation' doesn't exist")

The above exception was the direct cause of the following exception:

Traceback (most recent call last):
  File "C:\Users\Arulraj\AppData\Roaming\Python\Python313\site-packages\django\core\handlers\exception.py", line 55, in inner
    response = get_response(request)
  File "C:\Users\Arulraj\AppData\Roaming\Python\Python313\site-packages\django\core\handlers\base.py", line 197, in _get_response
    response = wrapped_callback(request, *callback_args, **callback_kwargs)
  File "C:\Users\Arulraj\AppData\Roaming\Python\Python313\site-packages\django\contrib\admin\options.py", line 688, in wrapper
    return self.admin_site.admin_view(view)(*args, **kwargs)
           ~~~~~~~~~~~~~~~~~~~~~~~~~~~~~~~~^^^^^^^^^^^^^^^^^
  File "C:\Users\Arulraj\AppData\Roaming\Python\Python313\site-packages\django\utils\decorators.py", line 134, in _wrapper_view
    response = view_func(request, *args, **kwargs)
  File "C:\Users\Arulraj\AppData\Roaming\Python\Python313\site-packages\django\views\decorators\cache.py", line 62, in _wrapper_view_func
    response = view_func(request, *args, **kwargs)
  File "C:\Users\Arulraj\AppData\Roaming\Python\Python313\site-packages\django\contrib\admin\sites.py", line 242, in inner
    return view(request, *args, **kwargs)
  File "C:\Users\Arulraj\AppData\Roaming\Python\Python313\site-packages\django\utils\decorators.py", line 46, in _wrapper
    return bound_method(*args, **kwargs)
  File "C:\Users\Arulraj\AppData\Roaming\Python\Python313\site-packages\django\utils\decorators.py", line 134, in _wrapper_view
    response = view_func(request, *args, **kwargs)
  File "C:\Users\Arulraj\AppData\Roaming\Python\Python313\site-packages\django\contrib\admin\options.py", line 1926, in changelist_view
    cl = self.get_changelist_instance(request)
  File "C:\Users\Arulraj\AppData\Roaming\Python\Python313\site-packages\django\contrib\admin\options.py", line 836, in get_changelist_instance
    return ChangeList(
        request,
    ...<12 lines>...
        self.search_help_text,
    )
  File "C:\Users\Arulraj\AppData\Roaming\Python\Python313\site-packages\django\contrib\admin\views\main.py", line 123, in __init__
    self.get_results(request)
    ~~~~~~~~~~~~~~~~^^^^^^^^^
  File "C:\Users\Arulraj\AppData\Roaming\Python\Python313\site-packages\django\contrib\admin\views\main.py", line 279, in get_results
    result_count = paginator.count
                   ^^^^^^^^^^^^^^^
  File "C:\Users\Arulraj\AppData\Roaming\Python\Python313\site-packages\django\utils\functional.py", line 57, in __get__
    res = instance.__dict__[self.name] = self.func(instance)
                                         ~~~~~~~~~^^^^^^^^^^
  File "C:\Users\Arulraj\AppData\Roaming\Python\Python313\site-packages\django\core\paginator.py", line 93, in count
    return c()
  File "C:\Users\Arulraj\AppData\Roaming\Python\Python313\site-packages\django\db\models\query.py", line 608, in count
    return self.query.get_count(using=self.db)
           ~~~~~~~~~~~~~~~~~~~~^^^^^^^^^^^^^^^
  File "C:\Users\Arulraj\AppData\Roaming\Python\Python313\site-packages\django\db\models\sql\query.py", line 568, in get_count
    return obj.get_aggregation(using, {"__count": Count("*")})["__count"]
           ~~~~~~~~~~~~~~~~~~~^^^^^^^^^^^^^^^^^^^^^^^^^^^^^^^^
  File "C:\Users\Arulraj\AppData\Roaming\Python\Python313\site-packages\django\db\models\sql\query.py", line 554, in get_aggregation
    result = compiler.execute_sql(SINGLE)
  File "C:\Users\Arulraj\AppData\Roaming\Python\Python313\site-packages\django\db\models\sql\compiler.py", line 1562, in execute_sql
    cursor.execute(sql, params)
    ~~~~~~~~~~~~~~^^^^^^^^^^^^^
  File "C:\Users\Arulraj\AppData\Roaming\Python\Python313\site-packages\django\db\backends\utils.py", line 102, in execute
    return super().execute(sql, params)
           ~~~~~~~~~~~~~~~^^^^^^^^^^^^^
  File "C:\Users\Arulraj\AppData\Roaming\Python\Python313\site-packages\django\db\backends\utils.py", line 67, in execute
    return self._execute_with_wrappers(
           ~~~~~~~~~~~~~~~~~~~~~~~~~~~^
        sql, params, many=False, executor=self._execute
        ^^^^^^^^^^^^^^^^^^^^^^^^^^^^^^^^^^^^^^^^^^^^^^^
    )
    ^
  File "C:\Users\Arulraj\AppData\Roaming\Python\Python313\site-packages\django\db\backends\utils.py", line 80, in _execute_with_wrappers
    return executor(sql, params, many, context)
  File "C:\Users\Arulraj\AppData\Roaming\Python\Python313\site-packages\django\db\backends\utils.py", line 84, in _execute
    with self.db.wrap_database_errors:
         ^^^^^^^^^^^^^^^^^^^^^^^^^^^^
  File "C:\Users\Arulraj\AppData\Roaming\Python\Python313\site-packages\django\db\utils.py", line 91, in __exit__
    raise dj_exc_value.with_traceback(traceback) from exc_value
  File "C:\Users\Arulraj\AppData\Roaming\Python\Python313\site-packages\django\db\backends\utils.py", line 89, in _execute
    return self.cursor.execute(sql, params)
           ~~~~~~~~~~~~~~~~~~~^^^^^^^^^^^^^
  File "C:\Users\Arulraj\AppData\Roaming\Python\Python313\site-packages\django\db\backends\mysql\base.py", line 75, in execute
    return self.cursor.execute(query, args)
           ~~~~~~~~~~~~~~~~~~~^^^^^^^^^^^^^
  File "C:\Users\Arulraj\AppData\Roaming\Python\Python313\site-packages\MySQLdb\cursors.py", line 179, in execute
    res = self._query(mogrified_query)
  File "C:\Users\Arulraj\AppData\Roaming\Python\Python313\site-packages\MySQLdb\cursors.py", line 330, in _query
    db.query(q)
    ~~~~~~~~^^^
  File "C:\Users\Arulraj\AppData\Roaming\Python\Python313\site-packages\MySQLdb\connections.py", line 280, in query
    _mysql.connection.query(self, query)
    ~~~~~~~~~~~~~~~~~~~~~~~^^^^^^^^^^^^^
django.db.utils.ProgrammingError: (1146, "Table 'skyplay_api_hub2.subscribe_activation' doesn't exist")
"GET /admin/subscribe/activation/ HTTP/1.1" 500 205097
Internal Server Error: /admin/subscribe/activation/
Traceback (most recent call last):
  File "C:\Users\Arulraj\AppData\Roaming\Python\Python313\site-packages\django\db\backends\utils.py", line 89, in _execute
    return self.cursor.execute(sql, params)
           ~~~~~~~~~~~~~~~~~~~^^^^^^^^^^^^^
  File "C:\Users\Arulraj\AppData\Roaming\Python\Python313\site-packages\django\db\backends\mysql\base.py", line 75, in execute
    return self.cursor.execute(query, args)
           ~~~~~~~~~~~~~~~~~~~^^^^^^^^^^^^^
  File "C:\Users\Arulraj\AppData\Roaming\Python\Python313\site-packages\MySQLdb\cursors.py", line 179, in execute
    res = self._query(mogrified_query)
  File "C:\Users\Arulraj\AppData\Roaming\Python\Python313\site-packages\MySQLdb\cursors.py", line 330, in _query
    db.query(q)
    ~~~~~~~~^^^
  File "C:\Users\Arulraj\AppData\Roaming\Python\Python313\site-packages\MySQLdb\connections.py", line 280, in query
    _mysql.connection.query(self, query)
    ~~~~~~~~~~~~~~~~~~~~~~~^^^^^^^^^^^^^
MySQLdb.ProgrammingError: (1146, "Table 'skyplay_api_hub2.subscribe_activation' doesn't exist")

The above exception was the direct cause of the following exception:

Traceback (most recent call last):
  File "C:\Users\Arulraj\AppData\Roaming\Python\Python313\site-packages\django\core\handlers\exception.py", line 55, in inner
    response = get_response(request)
  File "C:\Users\Arulraj\AppData\Roaming\Python\Python313\site-packages\django\core\handlers\base.py", line 197, in _get_response
    response = wrapped_callback(request, *callback_args, **callback_kwargs)
  File "C:\Users\Arulraj\AppData\Roaming\Python\Python313\site-packages\django\contrib\admin\options.py", line 688, in wrapper
    return self.admin_site.admin_view(view)(*args, **kwargs)
           ~~~~~~~~~~~~~~~~~~~~~~~~~~~~~~~~^^^^^^^^^^^^^^^^^
  File "C:\Users\Arulraj\AppData\Roaming\Python\Python313\site-packages\django\utils\decorators.py", line 134, in _wrapper_view
    response = view_func(request, *args, **kwargs)
  File "C:\Users\Arulraj\AppData\Roaming\Python\Python313\site-packages\django\views\decorators\cache.py", line 62, in _wrapper_view_func
    response = view_func(request, *args, **kwargs)
  File "C:\Users\Arulraj\AppData\Roaming\Python\Python313\site-packages\django\contrib\admin\sites.py", line 242, in inner
    return view(request, *args, **kwargs)
  File "C:\Users\Arulraj\AppData\Roaming\Python\Python313\site-packages\django\utils\decorators.py", line 46, in _wrapper
    return bound_method(*args, **kwargs)
  File "C:\Users\Arulraj\AppData\Roaming\Python\Python313\site-packages\django\utils\decorators.py", line 134, in _wrapper_view
    response = view_func(request, *args, **kwargs)
  File "C:\Users\Arulraj\AppData\Roaming\Python\Python313\site-packages\django\contrib\admin\options.py", line 1926, in changelist_view
    cl = self.get_changelist_instance(request)
  File "C:\Users\Arulraj\AppData\Roaming\Python\Python313\site-packages\django\contrib\admin\options.py", line 836, in get_changelist_instance
    return ChangeList(
        request,
    ...<12 lines>...
        self.search_help_text,
    )
  File "C:\Users\Arulraj\AppData\Roaming\Python\Python313\site-packages\django\contrib\admin\views\main.py", line 123, in __init__
    self.get_results(request)
    ~~~~~~~~~~~~~~~~^^^^^^^^^
  File "C:\Users\Arulraj\AppData\Roaming\Python\Python313\site-packages\django\contrib\admin\views\main.py", line 279, in get_results
    result_count = paginator.count
                   ^^^^^^^^^^^^^^^
  File "C:\Users\Arulraj\AppData\Roaming\Python\Python313\site-packages\django\utils\functional.py", line 57, in __get__
    res = instance.__dict__[self.name] = self.func(instance)
                                         ~~~~~~~~~^^^^^^^^^^
  File "C:\Users\Arulraj\AppData\Roaming\Python\Python313\site-packages\django\core\paginator.py", line 93, in count
    return c()
  File "C:\Users\Arulraj\AppData\Roaming\Python\Python313\site-packages\django\db\models\query.py", line 608, in count
    return self.query.get_count(using=self.db)
           ~~~~~~~~~~~~~~~~~~~~^^^^^^^^^^^^^^^
  File "C:\Users\Arulraj\AppData\Roaming\Python\Python313\site-packages\django\db\models\sql\query.py", line 568, in get_count
    return obj.get_aggregation(using, {"__count": Count("*")})["__count"]
           ~~~~~~~~~~~~~~~~~~~^^^^^^^^^^^^^^^^^^^^^^^^^^^^^^^^
  File "C:\Users\Arulraj\AppData\Roaming\Python\Python313\site-packages\django\db\models\sql\query.py", line 554, in get_aggregation
    result = compiler.execute_sql(SINGLE)
  File "C:\Users\Arulraj\AppData\Roaming\Python\Python313\site-packages\django\db\models\sql\compiler.py", line 1562, in execute_sql
    cursor.execute(sql, params)
    ~~~~~~~~~~~~~~^^^^^^^^^^^^^
  File "C:\Users\Arulraj\AppData\Roaming\Python\Python313\site-packages\django\db\backends\utils.py", line 102, in execute
    return super().execute(sql, params)
           ~~~~~~~~~~~~~~~^^^^^^^^^^^^^
  File "C:\Users\Arulraj\AppData\Roaming\Python\Python313\site-packages\django\db\backends\utils.py", line 67, in execute
    return self._execute_with_wrappers(
           ~~~~~~~~~~~~~~~~~~~~~~~~~~~^
        sql, params, many=False, executor=self._execute
        ^^^^^^^^^^^^^^^^^^^^^^^^^^^^^^^^^^^^^^^^^^^^^^^
    )
    ^
  File "C:\Users\Arulraj\AppData\Roaming\Python\Python313\site-packages\django\db\backends\utils.py", line 80, in _execute_with_wrappers
    return executor(sql, params, many, context)
  File "C:\Users\Arulraj\AppData\Roaming\Python\Python313\site-packages\django\db\backends\utils.py", line 84, in _execute
    with self.db.wrap_database_errors:
         ^^^^^^^^^^^^^^^^^^^^^^^^^^^^
  File "C:\Users\Arulraj\AppData\Roaming\Python\Python313\site-packages\django\db\utils.py", line 91, in __exit__
    raise dj_exc_value.with_traceback(traceback) from exc_value
  File "C:\Users\Arulraj\AppData\Roaming\Python\Python313\site-packages\django\db\backends\utils.py", line 89, in _execute
    return self.cursor.execute(sql, params)
           ~~~~~~~~~~~~~~~~~~~^^^^^^^^^^^^^
  File "C:\Users\Arulraj\AppData\Roaming\Python\Python313\site-packages\django\db\backends\mysql\base.py", line 75, in execute
    return self.cursor.execute(query, args)
           ~~~~~~~~~~~~~~~~~~~^^^^^^^^^^^^^
  File "C:\Users\Arulraj\AppData\Roaming\Python\Python313\site-packages\MySQLdb\cursors.py", line 179, in execute
    res = self._query(mogrified_query)
  File "C:\Users\Arulraj\AppData\Roaming\Python\Python313\site-packages\MySQLdb\cursors.py", line 330, in _query
    db.query(q)
    ~~~~~~~~^^^
  File "C:\Users\Arulraj\AppData\Roaming\Python\Python313\site-packages\MySQLdb\connections.py", line 280, in query
    _mysql.connection.query(self, query)
    ~~~~~~~~~~~~~~~~~~~~~~~^^^^^^^^^^^^^
django.db.utils.ProgrammingError: (1146, "Table 'skyplay_api_hub2.subscribe_activation' doesn't exist")
"GET /admin/subscribe/activation/ HTTP/1.1" 500 204960
Internal Server Error: /skyplay_api/set_subscribe_to_channel/33/2025-02-10/33/33/
"GET /skyplay_api/set_subscribe_to_channel/33/2025-02-10/33/33/ HTTP/1.1" 500 52
Internal Server Error: /admin/subscribe/paymentlog/
Traceback (most recent call last):
  File "C:\Users\Arulraj\AppData\Roaming\Python\Python313\site-packages\django\core\handlers\exception.py", line 55, in inner
    response = get_response(request)
  File "C:\Users\Arulraj\AppData\Roaming\Python\Python313\site-packages\django\core\handlers\base.py", line 197, in _get_response
    response = wrapped_callback(request, *callback_args, **callback_kwargs)
  File "C:\Users\Arulraj\AppData\Roaming\Python\Python313\site-packages\django\contrib\admin\options.py", line 688, in wrapper
    return self.admin_site.admin_view(view)(*args, **kwargs)
           ~~~~~~~~~~~~~~~~~~~~~~~~~~~~~~~~^^^^^^^^^^^^^^^^^
  File "C:\Users\Arulraj\AppData\Roaming\Python\Python313\site-packages\django\utils\decorators.py", line 134, in _wrapper_view
    response = view_func(request, *args, **kwargs)
  File "C:\Users\Arulraj\AppData\Roaming\Python\Python313\site-packages\django\views\decorators\cache.py", line 62, in _wrapper_view_func
    response = view_func(request, *args, **kwargs)
  File "C:\Users\Arulraj\AppData\Roaming\Python\Python313\site-packages\django\contrib\admin\sites.py", line 242, in inner
    return view(request, *args, **kwargs)
  File "C:\Users\Arulraj\AppData\Roaming\Python\Python313\site-packages\django\utils\decorators.py", line 46, in _wrapper
    return bound_method(*args, **kwargs)
  File "C:\Users\Arulraj\AppData\Roaming\Python\Python313\site-packages\django\utils\decorators.py", line 134, in _wrapper_view
    response = view_func(request, *args, **kwargs)
  File "C:\Users\Arulraj\AppData\Roaming\Python\Python313\site-packages\django\contrib\admin\options.py", line 2063, in changelist_view
    **self.admin_site.each_context(request),
      ~~~~~~~~~~~~~~~~~~~~~~~~~~~~^^^^^^^^^
  File "C:\Users\Arulraj\AppData\Roaming\Python\Python313\site-packages\django\contrib\admin\sites.py", line 337, in each_context
    "available_apps": self.get_app_list(request),
                      ~~~~~~~~~~~~~~~~~^^^^^^^^^
  File "C:\xampp\htdocs\skyplay_api_hub\skyplay_api\admin.py", line 14, in get_app_list
    app_list = super().get_app_list(request)
               ~~~~~^^
RuntimeError: super(): __class__ cell not found
"GET /admin/subscribe/paymentlog/ HTTP/1.1" 500 104752
Internal Server Error: /admin/subscribe/paymentlog/
Traceback (most recent call last):
  File "C:\Users\Arulraj\AppData\Roaming\Python\Python313\site-packages\django\core\handlers\exception.py", line 55, in inner
    response = get_response(request)
  File "C:\Users\Arulraj\AppData\Roaming\Python\Python313\site-packages\django\core\handlers\base.py", line 197, in _get_response
    response = wrapped_callback(request, *callback_args, **callback_kwargs)
  File "C:\Users\Arulraj\AppData\Roaming\Python\Python313\site-packages\django\contrib\admin\options.py", line 688, in wrapper
    return self.admin_site.admin_view(view)(*args, **kwargs)
           ~~~~~~~~~~~~~~~~~~~~~~~~~~~~~~~~^^^^^^^^^^^^^^^^^
  File "C:\Users\Arulraj\AppData\Roaming\Python\Python313\site-packages\django\utils\decorators.py", line 134, in _wrapper_view
    response = view_func(request, *args, **kwargs)
  File "C:\Users\Arulraj\AppData\Roaming\Python\Python313\site-packages\django\views\decorators\cache.py", line 62, in _wrapper_view_func
    response = view_func(request, *args, **kwargs)
  File "C:\Users\Arulraj\AppData\Roaming\Python\Python313\site-packages\django\contrib\admin\sites.py", line 242, in inner
    return view(request, *args, **kwargs)
  File "C:\Users\Arulraj\AppData\Roaming\Python\Python313\site-packages\django\utils\decorators.py", line 46, in _wrapper
    return bound_method(*args, **kwargs)
  File "C:\Users\Arulraj\AppData\Roaming\Python\Python313\site-packages\django\utils\decorators.py", line 134, in _wrapper_view
    response = view_func(request, *args, **kwargs)
  File "C:\Users\Arulraj\AppData\Roaming\Python\Python313\site-packages\django\contrib\admin\options.py", line 2063, in changelist_view
    **self.admin_site.each_context(request),
      ~~~~~~~~~~~~~~~~~~~~~~~~~~~~^^^^^^^^^
  File "C:\Users\Arulraj\AppData\Roaming\Python\Python313\site-packages\django\contrib\admin\sites.py", line 337, in each_context
    "available_apps": self.get_app_list(request),
                      ~~~~~~~~~~~~~~~~~^^^^^^^^^
  File "C:\xampp\htdocs\skyplay_api_hub\skyplay_api\admin.py", line 12, in get_app_list
    app_list = super().get_app_list(request)
               ~~~~~^^
RuntimeError: super(): __class__ cell not found
"GET /admin/subscribe/paymentlog/ HTTP/1.1" 500 104838
Internal Server Error: /admin/subscribe/activation/
Traceback (most recent call last):
  File "C:\Users\Arulraj\AppData\Roaming\Python\Python313\site-packages\django\core\handlers\exception.py", line 55, in inner
    response = get_response(request)
  File "C:\Users\Arulraj\AppData\Roaming\Python\Python313\site-packages\django\core\handlers\base.py", line 197, in _get_response
    response = wrapped_callback(request, *callback_args, **callback_kwargs)
  File "C:\Users\Arulraj\AppData\Roaming\Python\Python313\site-packages\django\contrib\admin\options.py", line 688, in wrapper
    return self.admin_site.admin_view(view)(*args, **kwargs)
           ~~~~~~~~~~~~~~~~~~~~~~~~~~~~~~~~^^^^^^^^^^^^^^^^^
  File "C:\Users\Arulraj\AppData\Roaming\Python\Python313\site-packages\django\utils\decorators.py", line 134, in _wrapper_view
    response = view_func(request, *args, **kwargs)
  File "C:\Users\Arulraj\AppData\Roaming\Python\Python313\site-packages\django\views\decorators\cache.py", line 62, in _wrapper_view_func
    response = view_func(request, *args, **kwargs)
  File "C:\Users\Arulraj\AppData\Roaming\Python\Python313\site-packages\django\contrib\admin\sites.py", line 242, in inner
    return view(request, *args, **kwargs)
  File "C:\Users\Arulraj\AppData\Roaming\Python\Python313\site-packages\django\utils\decorators.py", line 46, in _wrapper
    return bound_method(*args, **kwargs)
  File "C:\Users\Arulraj\AppData\Roaming\Python\Python313\site-packages\django\utils\decorators.py", line 134, in _wrapper_view
    response = view_func(request, *args, **kwargs)
  File "C:\Users\Arulraj\AppData\Roaming\Python\Python313\site-packages\django\contrib\admin\options.py", line 2063, in changelist_view
    **self.admin_site.each_context(request),
      ~~~~~~~~~~~~~~~~~~~~~~~~~~~~^^^^^^^^^
  File "C:\Users\Arulraj\AppData\Roaming\Python\Python313\site-packages\django\contrib\admin\sites.py", line 337, in each_context
    "available_apps": self.get_app_list(request),
                      ~~~~~~~~~~~~~~~~~^^^^^^^^^
  File "C:\xampp\htdocs\skyplay_api_hub\skyplay_api\admin.py", line 12, in get_app_list
    app_list = super().get_app_list(request)
               ~~~~~^^
RuntimeError: super(): __class__ cell not found
"GET /admin/subscribe/activation/ HTTP/1.1" 500 104738
Internal Server Error: /admin/skyplay_api/apilog/
Traceback (most recent call last):
  File "C:\Users\Arulraj\AppData\Roaming\Python\Python313\site-packages\django\core\handlers\exception.py", line 55, in inner
    response = get_response(request)
  File "C:\Users\Arulraj\AppData\Roaming\Python\Python313\site-packages\django\core\handlers\base.py", line 197, in _get_response
    response = wrapped_callback(request, *callback_args, **callback_kwargs)
  File "C:\Users\Arulraj\AppData\Roaming\Python\Python313\site-packages\django\contrib\admin\options.py", line 688, in wrapper
    return self.admin_site.admin_view(view)(*args, **kwargs)
           ~~~~~~~~~~~~~~~~~~~~~~~~~~~~~~~~^^^^^^^^^^^^^^^^^
  File "C:\Users\Arulraj\AppData\Roaming\Python\Python313\site-packages\django\utils\decorators.py", line 134, in _wrapper_view
    response = view_func(request, *args, **kwargs)
  File "C:\Users\Arulraj\AppData\Roaming\Python\Python313\site-packages\django\views\decorators\cache.py", line 62, in _wrapper_view_func
    response = view_func(request, *args, **kwargs)
  File "C:\Users\Arulraj\AppData\Roaming\Python\Python313\site-packages\django\contrib\admin\sites.py", line 242, in inner
    return view(request, *args, **kwargs)
  File "C:\Users\Arulraj\AppData\Roaming\Python\Python313\site-packages\django\utils\decorators.py", line 46, in _wrapper
    return bound_method(*args, **kwargs)
  File "C:\Users\Arulraj\AppData\Roaming\Python\Python313\site-packages\django\utils\decorators.py", line 134, in _wrapper_view
    response = view_func(request, *args, **kwargs)
  File "C:\Users\Arulraj\AppData\Roaming\Python\Python313\site-packages\django\contrib\admin\options.py", line 2063, in changelist_view
    **self.admin_site.each_context(request),
      ~~~~~~~~~~~~~~~~~~~~~~~~~~~~^^^^^^^^^
  File "C:\Users\Arulraj\AppData\Roaming\Python\Python313\site-packages\django\contrib\admin\sites.py", line 337, in each_context
    "available_apps": self.get_app_list(request),
                      ~~~~~~~~~~~~~~~~~^^^^^^^^^
  File "C:\xampp\htdocs\skyplay_api_hub\skyplay_api\admin.py", line 12, in get_app_list
    app_list = super().get_app_list(request)
               ~~~~~^^
RuntimeError: super(): __class__ cell not found
"GET /admin/skyplay_api/apilog/ HTTP/1.1" 500 104603
Internal Server Error: /admin/wallet/wallet/
Traceback (most recent call last):
  File "C:\Users\Arulraj\AppData\Roaming\Python\Python313\site-packages\django\core\handlers\exception.py", line 55, in inner
    response = get_response(request)
  File "C:\Users\Arulraj\AppData\Roaming\Python\Python313\site-packages\django\core\handlers\base.py", line 197, in _get_response
    response = wrapped_callback(request, *callback_args, **callback_kwargs)
  File "C:\Users\Arulraj\AppData\Roaming\Python\Python313\site-packages\django\contrib\admin\options.py", line 688, in wrapper
    return self.admin_site.admin_view(view)(*args, **kwargs)
           ~~~~~~~~~~~~~~~~~~~~~~~~~~~~~~~~^^^^^^^^^^^^^^^^^
  File "C:\Users\Arulraj\AppData\Roaming\Python\Python313\site-packages\django\utils\decorators.py", line 134, in _wrapper_view
    response = view_func(request, *args, **kwargs)
  File "C:\Users\Arulraj\AppData\Roaming\Python\Python313\site-packages\django\views\decorators\cache.py", line 62, in _wrapper_view_func
    response = view_func(request, *args, **kwargs)
  File "C:\Users\Arulraj\AppData\Roaming\Python\Python313\site-packages\django\contrib\admin\sites.py", line 242, in inner
    return view(request, *args, **kwargs)
  File "C:\xampp\htdocs\skyplay_api_hub\wallet\admin.py", line 24, in changelist_view
    return super().changelist_view(request, extra_context)
           ~~~~~~~~~~~~~~~~~~~~~~~^^^^^^^^^^^^^^^^^^^^^^^^
  File "C:\Users\Arulraj\AppData\Roaming\Python\Python313\site-packages\django\utils\decorators.py", line 46, in _wrapper
    return bound_method(*args, **kwargs)
  File "C:\Users\Arulraj\AppData\Roaming\Python\Python313\site-packages\django\utils\decorators.py", line 134, in _wrapper_view
    response = view_func(request, *args, **kwargs)
  File "C:\Users\Arulraj\AppData\Roaming\Python\Python313\site-packages\django\contrib\admin\options.py", line 2063, in changelist_view
    **self.admin_site.each_context(request),
      ~~~~~~~~~~~~~~~~~~~~~~~~~~~~^^^^^^^^^
  File "C:\Users\Arulraj\AppData\Roaming\Python\Python313\site-packages\django\contrib\admin\sites.py", line 337, in each_context
    "available_apps": self.get_app_list(request),
                      ~~~~~~~~~~~~~~~~~^^^^^^^^^
  File "C:\xampp\htdocs\skyplay_api_hub\skyplay_api\admin.py", line 12, in get_app_list
    app_list = super().get_app_list(request)
               ~~~~~^^
RuntimeError: super(): __class__ cell not found
"GET /admin/wallet/wallet/ HTTP/1.1" 500 109048
Internal Server Error: /admin/
Traceback (most recent call last):
  File "C:\Users\Arulraj\AppData\Roaming\Python\Python313\site-packages\django\core\handlers\exception.py", line 55, in inner
    response = get_response(request)
  File "C:\Users\Arulraj\AppData\Roaming\Python\Python313\site-packages\django\core\handlers\base.py", line 197, in _get_response
    response = wrapped_callback(request, *callback_args, **callback_kwargs)
  File "C:\Users\Arulraj\AppData\Roaming\Python\Python313\site-packages\django\contrib\admin\sites.py", line 261, in wrapper
    return self.admin_view(view, cacheable)(*args, **kwargs)
           ~~~~~~~~~~~~~~~~~~~~~~~~~~~~~~~~^^^^^^^^^^^^^^^^^
  File "C:\Users\Arulraj\AppData\Roaming\Python\Python313\site-packages\django\utils\decorators.py", line 134, in _wrapper_view
    response = view_func(request, *args, **kwargs)
  File "C:\Users\Arulraj\AppData\Roaming\Python\Python313\site-packages\django\views\decorators\cache.py", line 62, in _wrapper_view_func
    response = view_func(request, *args, **kwargs)
  File "C:\Users\Arulraj\AppData\Roaming\Python\Python313\site-packages\django\contrib\admin\sites.py", line 242, in inner
    return view(request, *args, **kwargs)
  File "C:\Users\Arulraj\AppData\Roaming\Python\Python313\site-packages\django\contrib\admin\sites.py", line 552, in index
    app_list = self.get_app_list(request)
  File "C:\xampp\htdocs\skyplay_api_hub\skyplay_api\admin.py", line 12, in get_app_list
    app_list = super().get_app_list(request)
               ~~~~~^^
RuntimeError: super(): __class__ cell not found
"GET /admin/ HTTP/1.1" 500 86961
Internal Server Error: /admin/
Traceback (most recent call last):
  File "C:\Users\Arulraj\AppData\Roaming\Python\Python313\site-packages\django\core\handlers\exception.py", line 55, in inner
    response = get_response(request)
  File "C:\Users\Arulraj\AppData\Roaming\Python\Python313\site-packages\django\core\handlers\base.py", line 197, in _get_response
    response = wrapped_callback(request, *callback_args, **callback_kwargs)
  File "C:\Users\Arulraj\AppData\Roaming\Python\Python313\site-packages\django\contrib\admin\sites.py", line 261, in wrapper
    return self.admin_view(view, cacheable)(*args, **kwargs)
           ~~~~~~~~~~~~~~~~~~~~~~~~~~~~~~~~^^^^^^^^^^^^^^^^^
  File "C:\Users\Arulraj\AppData\Roaming\Python\Python313\site-packages\django\utils\decorators.py", line 134, in _wrapper_view
    response = view_func(request, *args, **kwargs)
  File "C:\Users\Arulraj\AppData\Roaming\Python\Python313\site-packages\django\views\decorators\cache.py", line 62, in _wrapper_view_func
    response = view_func(request, *args, **kwargs)
  File "C:\Users\Arulraj\AppData\Roaming\Python\Python313\site-packages\django\contrib\admin\sites.py", line 242, in inner
    return view(request, *args, **kwargs)
  File "C:\Users\Arulraj\AppData\Roaming\Python\Python313\site-packages\django\contrib\admin\sites.py", line 552, in index
    app_list = self.get_app_list(request)
  File "C:\xampp\htdocs\skyplay_api_hub\skyplay_api\admin.py", line 12, in get_app_list
    app_list = super().get_app_list(request)
               ~~~~~^^
RuntimeError: super(): __class__ cell not found
"GET /admin/ HTTP/1.1" 500 87119
Internal Server Error: /admin/
Traceback (most recent call last):
  File "C:\Users\Arulraj\AppData\Roaming\Python\Python313\site-packages\django\core\handlers\exception.py", line 55, in inner
    response = get_response(request)
  File "C:\Users\Arulraj\AppData\Roaming\Python\Python313\site-packages\django\core\handlers\base.py", line 197, in _get_response
    response = wrapped_callback(request, *callback_args, **callback_kwargs)
  File "C:\Users\Arulraj\AppData\Roaming\Python\Python313\site-packages\django\contrib\admin\sites.py", line 261, in wrapper
    return self.admin_view(view, cacheable)(*args, **kwargs)
           ~~~~~~~~~~~~~~~~~~~~~~~~~~~~~~~~^^^^^^^^^^^^^^^^^
  File "C:\Users\Arulraj\AppData\Roaming\Python\Python313\site-packages\django\utils\decorators.py", line 134, in _wrapper_view
    response = view_func(request, *args, **kwargs)
  File "C:\Users\Arulraj\AppData\Roaming\Python\Python313\site-packages\django\views\decorators\cache.py", line 62, in _wrapper_view_func
    response = view_func(request, *args, **kwargs)
  File "C:\Users\Arulraj\AppData\Roaming\Python\Python313\site-packages\django\contrib\admin\sites.py", line 242, in inner
    return view(request, *args, **kwargs)
  File "C:\Users\Arulraj\AppData\Roaming\Python\Python313\site-packages\django\contrib\admin\sites.py", line 552, in index
    app_list = self.get_app_list(request)
  File "C:\xampp\htdocs\skyplay_api_hub\skyplay_api\admin.py", line 12, in get_app_list
    app_list = super().get_app_list(request)
               ~~~~~^^
RuntimeError: super(): __class__ cell not found
"GET /admin/ HTTP/1.1" 500 86961
Internal Server Error: /admin/
Traceback (most recent call last):
  File "C:\Users\Arulraj\AppData\Roaming\Python\Python313\site-packages\django\core\handlers\exception.py", line 55, in inner
    response = get_response(request)
  File "C:\Users\Arulraj\AppData\Roaming\Python\Python313\site-packages\django\core\handlers\base.py", line 197, in _get_response
    response = wrapped_callback(request, *callback_args, **callback_kwargs)
  File "C:\Users\Arulraj\AppData\Roaming\Python\Python313\site-packages\django\contrib\admin\sites.py", line 261, in wrapper
    return self.admin_view(view, cacheable)(*args, **kwargs)
           ~~~~~~~~~~~~~~~~~~~~~~~~~~~~~~~~^^^^^^^^^^^^^^^^^
  File "C:\Users\Arulraj\AppData\Roaming\Python\Python313\site-packages\django\utils\decorators.py", line 134, in _wrapper_view
    response = view_func(request, *args, **kwargs)
  File "C:\Users\Arulraj\AppData\Roaming\Python\Python313\site-packages\django\views\decorators\cache.py", line 62, in _wrapper_view_func
    response = view_func(request, *args, **kwargs)
  File "C:\Users\Arulraj\AppData\Roaming\Python\Python313\site-packages\django\contrib\admin\sites.py", line 242, in inner
    return view(request, *args, **kwargs)
  File "C:\Users\Arulraj\AppData\Roaming\Python\Python313\site-packages\django\contrib\admin\sites.py", line 552, in index
    app_list = self.get_app_list(request)
  File "C:\xampp\htdocs\skyplay_api_hub\skyplay_api\admin.py", line 12, in get_app_list
    app_list = super().get_app_list(request)
               ~~~~~^^
RuntimeError: super(): __class__ cell not found
"GET /admin/ HTTP/1.1" 500 87101
Internal Server Error: /wallet/
Traceback (most recent call last):
  File "C:\Users\Arulraj\AppData\Roaming\Python\Python313\site-packages\django\template\backends\django.py", line 61, in render
    return self.template.render(context)
           ~~~~~~~~~~~~~~~~~~~~^^^^^^^^^
  File "C:\Users\Arulraj\AppData\Roaming\Python\Python313\site-packages\django\template\base.py", line 175, in render
    return self._render(context)
           ~~~~~~~~~~~~^^^^^^^^^
  File "C:\Users\Arulraj\AppData\Roaming\Python\Python313\site-packages\django\template\base.py", line 167, in _render
    return self.nodelist.render(context)
           ~~~~~~~~~~~~~~~~~~~~^^^^^^^^^
  File "C:\Users\Arulraj\AppData\Roaming\Python\Python313\site-packages\django\template\base.py", line 1005, in render
    return SafeString("".join([node.render_annotated(context) for node in self]))
                               ~~~~~~~~~~~~~~~~~~~~~^^^^^^^^^
  File "C:\Users\Arulraj\AppData\Roaming\Python\Python313\site-packages\django\template\base.py", line 966, in render_annotated
    return self.render(context)
           ~~~~~~~~~~~^^^^^^^^^
  File "C:\Users\Arulraj\AppData\Roaming\Python\Python313\site-packages\django\template\loader_tags.py", line 157, in render
    return compiled_parent._render(context)
           ~~~~~~~~~~~~~~~~~~~~~~~^^^^^^^^^
  File "C:\Users\Arulraj\AppData\Roaming\Python\Python313\site-packages\django\template\base.py", line 167, in _render
    return self.nodelist.render(context)
           ~~~~~~~~~~~~~~~~~~~~^^^^^^^^^
  File "C:\Users\Arulraj\AppData\Roaming\Python\Python313\site-packages\django\template\base.py", line 1005, in render
    return SafeString("".join([node.render_annotated(context) for node in self]))
                               ~~~~~~~~~~~~~~~~~~~~~^^^^^^^^^
  File "C:\Users\Arulraj\AppData\Roaming\Python\Python313\site-packages\django\template\base.py", line 966, in render_annotated
    return self.render(context)
           ~~~~~~~~~~~^^^^^^^^^
  File "C:\Users\Arulraj\AppData\Roaming\Python\Python313\site-packages\django\template\loader_tags.py", line 157, in render
    return compiled_parent._render(context)
           ~~~~~~~~~~~~~~~~~~~~~~~^^^^^^^^^
  File "C:\Users\Arulraj\AppData\Roaming\Python\Python313\site-packages\django\template\base.py", line 167, in _render
    return self.nodelist.render(context)
           ~~~~~~~~~~~~~~~~~~~~^^^^^^^^^
  File "C:\Users\Arulraj\AppData\Roaming\Python\Python313\site-packages\django\template\base.py", line 1005, in render
    return SafeString("".join([node.render_annotated(context) for node in self]))
                               ~~~~~~~~~~~~~~~~~~~~~^^^^^^^^^
  File "C:\Users\Arulraj\AppData\Roaming\Python\Python313\site-packages\django\template\base.py", line 966, in render_annotated
    return self.render(context)
           ~~~~~~~~~~~^^^^^^^^^
  File "C:\Users\Arulraj\AppData\Roaming\Python\Python313\site-packages\django\template\defaulttags.py", line 321, in render
    return nodelist.render(context)
           ~~~~~~~~~~~~~~~^^^^^^^^^
  File "C:\Users\Arulraj\AppData\Roaming\Python\Python313\site-packages\django\template\base.py", line 1005, in render
    return SafeString("".join([node.render_annotated(context) for node in self]))
                               ~~~~~~~~~~~~~~~~~~~~~^^^^^^^^^
  File "C:\Users\Arulraj\AppData\Roaming\Python\Python313\site-packages\django\template\base.py", line 966, in render_annotated
    return self.render(context)
           ~~~~~~~~~~~^^^^^^^^^
  File "C:\Users\Arulraj\AppData\Roaming\Python\Python313\site-packages\django\template\loader_tags.py", line 63, in render
    result = block.nodelist.render(context)
  File "C:\Users\Arulraj\AppData\Roaming\Python\Python313\site-packages\django\template\base.py", line 1005, in render
    return SafeString("".join([node.render_annotated(context) for node in self]))
                               ~~~~~~~~~~~~~~~~~~~~~^^^^^^^^^
  File "C:\Users\Arulraj\AppData\Roaming\Python\Python313\site-packages\django\template\base.py", line 966, in render_annotated
    return self.render(context)
           ~~~~~~~~~~~^^^^^^^^^
  File "C:\Users\Arulraj\AppData\Roaming\Python\Python313\site-packages\django\template\loader_tags.py", line 63, in render
    result = block.nodelist.render(context)
  File "C:\Users\Arulraj\AppData\Roaming\Python\Python313\site-packages\django\template\base.py", line 1005, in render
    return SafeString("".join([node.render_annotated(context) for node in self]))
                               ~~~~~~~~~~~~~~~~~~~~~^^^^^^^^^
  File "C:\Users\Arulraj\AppData\Roaming\Python\Python313\site-packages\django\template\base.py", line 966, in render_annotated
    return self.render(context)
           ~~~~~~~~~~~^^^^^^^^^
  File "C:\Users\Arulraj\AppData\Roaming\Python\Python313\site-packages\django\template\loader_tags.py", line 197, in render
    template = context.template.engine.select_template(template_name)
  File "C:\Users\Arulraj\AppData\Roaming\Python\Python313\site-packages\django\template\engine.py", line 212, in select_template
    raise TemplateDoesNotExist(", ".join(not_found))
django.template.exceptions.TemplateDoesNotExist: admin/includes/nav-global.html

The above exception was the direct cause of the following exception:

Traceback (most recent call last):
  File "C:\Users\Arulraj\AppData\Roaming\Python\Python313\site-packages\django\core\handlers\exception.py", line 55, in inner
    response = get_response(request)
  File "C:\Users\Arulraj\AppData\Roaming\Python\Python313\site-packages\django\core\handlers\base.py", line 197, in _get_response
    response = wrapped_callback(request, *callback_args, **callback_kwargs)
  File "C:\Users\Arulraj\AppData\Roaming\Python\Python313\site-packages\django\contrib\auth\decorators.py", line 23, in _wrapper_view
    return view_func(request, *args, **kwargs)
  File "C:\xampp\htdocs\skyplay_api_hub\wallet\views.py", line 33, in wallet_view
    return render(request, 'wallet/wallet.html', {'wallet': wallet, 'razorpay_key': RAZORPAY_KEY_ID, 'user_id': user_id ,  'transactions': transactions})
  File "C:\Users\Arulraj\AppData\Roaming\Python\Python313\site-packages\django\shortcuts.py", line 24, in render
    content = loader.render_to_string(template_name, context, request, using=using)
  File "C:\Users\Arulraj\AppData\Roaming\Python\Python313\site-packages\django\template\loader.py", line 62, in render_to_string
    return template.render(context, request)
           ~~~~~~~~~~~~~~~^^^^^^^^^^^^^^^^^^
  File "C:\Users\Arulraj\AppData\Roaming\Python\Python313\site-packages\django\template\backends\django.py", line 63, in render
    reraise(exc, self.backend)
    ~~~~~~~^^^^^^^^^^^^^^^^^^^
  File "C:\Users\Arulraj\AppData\Roaming\Python\Python313\site-packages\django\template\backends\django.py", line 84, in reraise
    raise new from exc
django.template.exceptions.TemplateDoesNotExist: admin/includes/nav-global.html
"GET /wallet/ HTTP/1.1" 500 246849
Internal Server Error: /wallet/
Traceback (most recent call last):
  File "C:\Users\Arulraj\AppData\Roaming\Python\Python313\site-packages\django\template\backends\django.py", line 61, in render
    return self.template.render(context)
           ~~~~~~~~~~~~~~~~~~~~^^^^^^^^^
  File "C:\Users\Arulraj\AppData\Roaming\Python\Python313\site-packages\django\template\base.py", line 175, in render
    return self._render(context)
           ~~~~~~~~~~~~^^^^^^^^^
  File "C:\Users\Arulraj\AppData\Roaming\Python\Python313\site-packages\django\template\base.py", line 167, in _render
    return self.nodelist.render(context)
           ~~~~~~~~~~~~~~~~~~~~^^^^^^^^^
  File "C:\Users\Arulraj\AppData\Roaming\Python\Python313\site-packages\django\template\base.py", line 1005, in render
    return SafeString("".join([node.render_annotated(context) for node in self]))
                               ~~~~~~~~~~~~~~~~~~~~~^^^^^^^^^
  File "C:\Users\Arulraj\AppData\Roaming\Python\Python313\site-packages\django\template\base.py", line 966, in render_annotated
    return self.render(context)
           ~~~~~~~~~~~^^^^^^^^^
  File "C:\Users\Arulraj\AppData\Roaming\Python\Python313\site-packages\django\template\loader_tags.py", line 157, in render
    return compiled_parent._render(context)
           ~~~~~~~~~~~~~~~~~~~~~~~^^^^^^^^^
  File "C:\Users\Arulraj\AppData\Roaming\Python\Python313\site-packages\django\template\base.py", line 167, in _render
    return self.nodelist.render(context)
           ~~~~~~~~~~~~~~~~~~~~^^^^^^^^^
  File "C:\Users\Arulraj\AppData\Roaming\Python\Python313\site-packages\django\template\base.py", line 1005, in render
    return SafeString("".join([node.render_annotated(context) for node in self]))
                               ~~~~~~~~~~~~~~~~~~~~~^^^^^^^^^
  File "C:\Users\Arulraj\AppData\Roaming\Python\Python313\site-packages\django\template\base.py", line 966, in render_annotated
    return self.render(context)
           ~~~~~~~~~~~^^^^^^^^^
  File "C:\Users\Arulraj\AppData\Roaming\Python\Python313\site-packages\django\template\loader_tags.py", line 157, in render
    return compiled_parent._render(context)
           ~~~~~~~~~~~~~~~~~~~~~~~^^^^^^^^^
  File "C:\Users\Arulraj\AppData\Roaming\Python\Python313\site-packages\django\template\base.py", line 167, in _render
    return self.nodelist.render(context)
           ~~~~~~~~~~~~~~~~~~~~^^^^^^^^^
  File "C:\Users\Arulraj\AppData\Roaming\Python\Python313\site-packages\django\template\base.py", line 1005, in render
    return SafeString("".join([node.render_annotated(context) for node in self]))
                               ~~~~~~~~~~~~~~~~~~~~~^^^^^^^^^
  File "C:\Users\Arulraj\AppData\Roaming\Python\Python313\site-packages\django\template\base.py", line 966, in render_annotated
    return self.render(context)
           ~~~~~~~~~~~^^^^^^^^^
  File "C:\Users\Arulraj\AppData\Roaming\Python\Python313\site-packages\django\template\defaulttags.py", line 321, in render
    return nodelist.render(context)
           ~~~~~~~~~~~~~~~^^^^^^^^^
  File "C:\Users\Arulraj\AppData\Roaming\Python\Python313\site-packages\django\template\base.py", line 1005, in render
    return SafeString("".join([node.render_annotated(context) for node in self]))
                               ~~~~~~~~~~~~~~~~~~~~~^^^^^^^^^
  File "C:\Users\Arulraj\AppData\Roaming\Python\Python313\site-packages\django\template\base.py", line 966, in render_annotated
    return self.render(context)
           ~~~~~~~~~~~^^^^^^^^^
  File "C:\Users\Arulraj\AppData\Roaming\Python\Python313\site-packages\django\template\loader_tags.py", line 63, in render
    result = block.nodelist.render(context)
  File "C:\Users\Arulraj\AppData\Roaming\Python\Python313\site-packages\django\template\base.py", line 1005, in render
    return SafeString("".join([node.render_annotated(context) for node in self]))
                               ~~~~~~~~~~~~~~~~~~~~~^^^^^^^^^
  File "C:\Users\Arulraj\AppData\Roaming\Python\Python313\site-packages\django\template\base.py", line 966, in render_annotated
    return self.render(context)
           ~~~~~~~~~~~^^^^^^^^^
  File "C:\Users\Arulraj\AppData\Roaming\Python\Python313\site-packages\django\template\loader_tags.py", line 63, in render
    result = block.nodelist.render(context)
  File "C:\Users\Arulraj\AppData\Roaming\Python\Python313\site-packages\django\template\base.py", line 1005, in render
    return SafeString("".join([node.render_annotated(context) for node in self]))
                               ~~~~~~~~~~~~~~~~~~~~~^^^^^^^^^
  File "C:\Users\Arulraj\AppData\Roaming\Python\Python313\site-packages\django\template\base.py", line 966, in render_annotated
    return self.render(context)
           ~~~~~~~~~~~^^^^^^^^^
  File "C:\Users\Arulraj\AppData\Roaming\Python\Python313\site-packages\django\template\loader_tags.py", line 197, in render
    template = context.template.engine.select_template(template_name)
  File "C:\Users\Arulraj\AppData\Roaming\Python\Python313\site-packages\django\template\engine.py", line 212, in select_template
    raise TemplateDoesNotExist(", ".join(not_found))
django.template.exceptions.TemplateDoesNotExist: admin/includes/nav-global.html

The above exception was the direct cause of the following exception:

Traceback (most recent call last):
  File "C:\Users\Arulraj\AppData\Roaming\Python\Python313\site-packages\django\core\handlers\exception.py", line 55, in inner
    response = get_response(request)
  File "C:\Users\Arulraj\AppData\Roaming\Python\Python313\site-packages\django\core\handlers\base.py", line 197, in _get_response
    response = wrapped_callback(request, *callback_args, **callback_kwargs)
  File "C:\Users\Arulraj\AppData\Roaming\Python\Python313\site-packages\django\contrib\auth\decorators.py", line 23, in _wrapper_view
    return view_func(request, *args, **kwargs)
  File "C:\xampp\htdocs\skyplay_api_hub\wallet\views.py", line 33, in wallet_view
    return render(request, 'wallet/wallet.html', {'wallet': wallet, 'razorpay_key': RAZORPAY_KEY_ID, 'user_id': user_id ,  'transactions': transactions})
  File "C:\Users\Arulraj\AppData\Roaming\Python\Python313\site-packages\django\shortcuts.py", line 24, in render
    content = loader.render_to_string(template_name, context, request, using=using)
  File "C:\Users\Arulraj\AppData\Roaming\Python\Python313\site-packages\django\template\loader.py", line 62, in render_to_string
    return template.render(context, request)
           ~~~~~~~~~~~~~~~^^^^^^^^^^^^^^^^^^
  File "C:\Users\Arulraj\AppData\Roaming\Python\Python313\site-packages\django\template\backends\django.py", line 63, in render
    reraise(exc, self.backend)
    ~~~~~~~^^^^^^^^^^^^^^^^^^^
  File "C:\Users\Arulraj\AppData\Roaming\Python\Python313\site-packages\django\template\backends\django.py", line 84, in reraise
    raise new from exc
django.template.exceptions.TemplateDoesNotExist: admin/includes/nav-global.html
"GET /wallet/ HTTP/1.1" 500 246945
Internal Server Error: /wallet/
Traceback (most recent call last):
  File "C:\Users\Arulraj\AppData\Roaming\Python\Python313\site-packages\django\template\backends\django.py", line 61, in render
    return self.template.render(context)
           ~~~~~~~~~~~~~~~~~~~~^^^^^^^^^
  File "C:\Users\Arulraj\AppData\Roaming\Python\Python313\site-packages\django\template\base.py", line 175, in render
    return self._render(context)
           ~~~~~~~~~~~~^^^^^^^^^
  File "C:\Users\Arulraj\AppData\Roaming\Python\Python313\site-packages\django\template\base.py", line 167, in _render
    return self.nodelist.render(context)
           ~~~~~~~~~~~~~~~~~~~~^^^^^^^^^
  File "C:\Users\Arulraj\AppData\Roaming\Python\Python313\site-packages\django\template\base.py", line 1005, in render
    return SafeString("".join([node.render_annotated(context) for node in self]))
                               ~~~~~~~~~~~~~~~~~~~~~^^^^^^^^^
  File "C:\Users\Arulraj\AppData\Roaming\Python\Python313\site-packages\django\template\base.py", line 966, in render_annotated
    return self.render(context)
           ~~~~~~~~~~~^^^^^^^^^
  File "C:\Users\Arulraj\AppData\Roaming\Python\Python313\site-packages\django\template\loader_tags.py", line 157, in render
    return compiled_parent._render(context)
           ~~~~~~~~~~~~~~~~~~~~~~~^^^^^^^^^
  File "C:\Users\Arulraj\AppData\Roaming\Python\Python313\site-packages\django\template\base.py", line 167, in _render
    return self.nodelist.render(context)
           ~~~~~~~~~~~~~~~~~~~~^^^^^^^^^
  File "C:\Users\Arulraj\AppData\Roaming\Python\Python313\site-packages\django\template\base.py", line 1005, in render
    return SafeString("".join([node.render_annotated(context) for node in self]))
                               ~~~~~~~~~~~~~~~~~~~~~^^^^^^^^^
  File "C:\Users\Arulraj\AppData\Roaming\Python\Python313\site-packages\django\template\base.py", line 966, in render_annotated
    return self.render(context)
           ~~~~~~~~~~~^^^^^^^^^
  File "C:\Users\Arulraj\AppData\Roaming\Python\Python313\site-packages\django\template\loader_tags.py", line 157, in render
    return compiled_parent._render(context)
           ~~~~~~~~~~~~~~~~~~~~~~~^^^^^^^^^
  File "C:\Users\Arulraj\AppData\Roaming\Python\Python313\site-packages\django\template\base.py", line 167, in _render
    return self.nodelist.render(context)
           ~~~~~~~~~~~~~~~~~~~~^^^^^^^^^
  File "C:\Users\Arulraj\AppData\Roaming\Python\Python313\site-packages\django\template\base.py", line 1005, in render
    return SafeString("".join([node.render_annotated(context) for node in self]))
                               ~~~~~~~~~~~~~~~~~~~~~^^^^^^^^^
  File "C:\Users\Arulraj\AppData\Roaming\Python\Python313\site-packages\django\template\base.py", line 966, in render_annotated
    return self.render(context)
           ~~~~~~~~~~~^^^^^^^^^
  File "C:\Users\Arulraj\AppData\Roaming\Python\Python313\site-packages\django\template\defaulttags.py", line 321, in render
    return nodelist.render(context)
           ~~~~~~~~~~~~~~~^^^^^^^^^
  File "C:\Users\Arulraj\AppData\Roaming\Python\Python313\site-packages\django\template\base.py", line 1005, in render
    return SafeString("".join([node.render_annotated(context) for node in self]))
                               ~~~~~~~~~~~~~~~~~~~~~^^^^^^^^^
  File "C:\Users\Arulraj\AppData\Roaming\Python\Python313\site-packages\django\template\base.py", line 966, in render_annotated
    return self.render(context)
           ~~~~~~~~~~~^^^^^^^^^
  File "C:\Users\Arulraj\AppData\Roaming\Python\Python313\site-packages\django\template\loader_tags.py", line 63, in render
    result = block.nodelist.render(context)
  File "C:\Users\Arulraj\AppData\Roaming\Python\Python313\site-packages\django\template\base.py", line 1005, in render
    return SafeString("".join([node.render_annotated(context) for node in self]))
                               ~~~~~~~~~~~~~~~~~~~~~^^^^^^^^^
  File "C:\Users\Arulraj\AppData\Roaming\Python\Python313\site-packages\django\template\base.py", line 966, in render_annotated
    return self.render(context)
           ~~~~~~~~~~~^^^^^^^^^
  File "C:\Users\Arulraj\AppData\Roaming\Python\Python313\site-packages\django\template\loader_tags.py", line 63, in render
    result = block.nodelist.render(context)
  File "C:\Users\Arulraj\AppData\Roaming\Python\Python313\site-packages\django\template\base.py", line 1005, in render
    return SafeString("".join([node.render_annotated(context) for node in self]))
                               ~~~~~~~~~~~~~~~~~~~~~^^^^^^^^^
  File "C:\Users\Arulraj\AppData\Roaming\Python\Python313\site-packages\django\template\base.py", line 966, in render_annotated
    return self.render(context)
           ~~~~~~~~~~~^^^^^^^^^
  File "C:\Users\Arulraj\AppData\Roaming\Python\Python313\site-packages\django\template\loader_tags.py", line 197, in render
    template = context.template.engine.select_template(template_name)
  File "C:\Users\Arulraj\AppData\Roaming\Python\Python313\site-packages\django\template\engine.py", line 212, in select_template
    raise TemplateDoesNotExist(", ".join(not_found))
django.template.exceptions.TemplateDoesNotExist: admin/includes/nav-global.html

The above exception was the direct cause of the following exception:

Traceback (most recent call last):
  File "C:\Users\Arulraj\AppData\Roaming\Python\Python313\site-packages\django\core\handlers\exception.py", line 55, in inner
    response = get_response(request)
  File "C:\Users\Arulraj\AppData\Roaming\Python\Python313\site-packages\django\core\handlers\base.py", line 197, in _get_response
    response = wrapped_callback(request, *callback_args, **callback_kwargs)
  File "C:\Users\Arulraj\AppData\Roaming\Python\Python313\site-packages\django\contrib\auth\decorators.py", line 23, in _wrapper_view
    return view_func(request, *args, **kwargs)
  File "C:\xampp\htdocs\skyplay_api_hub\wallet\views.py", line 33, in wallet_view
    return render(request, 'wallet/wallet.html', {'wallet': wallet, 'razorpay_key': RAZORPAY_KEY_ID, 'user_id': user_id ,  'transactions': transactions})
  File "C:\Users\Arulraj\AppData\Roaming\Python\Python313\site-packages\django\shortcuts.py", line 24, in render
    content = loader.render_to_string(template_name, context, request, using=using)
  File "C:\Users\Arulraj\AppData\Roaming\Python\Python313\site-packages\django\template\loader.py", line 62, in render_to_string
    return template.render(context, request)
           ~~~~~~~~~~~~~~~^^^^^^^^^^^^^^^^^^
  File "C:\Users\Arulraj\AppData\Roaming\Python\Python313\site-packages\django\template\backends\django.py", line 63, in render
    reraise(exc, self.backend)
    ~~~~~~~^^^^^^^^^^^^^^^^^^^
  File "C:\Users\Arulraj\AppData\Roaming\Python\Python313\site-packages\django\template\backends\django.py", line 84, in reraise
    raise new from exc
django.template.exceptions.TemplateDoesNotExist: admin/includes/nav-global.html
"GET /wallet/ HTTP/1.1" 500 247871
Internal Server Error: /wallet/
Traceback (most recent call last):
  File "C:\Users\Arulraj\AppData\Roaming\Python\Python313\site-packages\django\template\backends\django.py", line 61, in render
    return self.template.render(context)
           ~~~~~~~~~~~~~~~~~~~~^^^^^^^^^
  File "C:\Users\Arulraj\AppData\Roaming\Python\Python313\site-packages\django\template\base.py", line 175, in render
    return self._render(context)
           ~~~~~~~~~~~~^^^^^^^^^
  File "C:\Users\Arulraj\AppData\Roaming\Python\Python313\site-packages\django\template\base.py", line 167, in _render
    return self.nodelist.render(context)
           ~~~~~~~~~~~~~~~~~~~~^^^^^^^^^
  File "C:\Users\Arulraj\AppData\Roaming\Python\Python313\site-packages\django\template\base.py", line 1005, in render
    return SafeString("".join([node.render_annotated(context) for node in self]))
                               ~~~~~~~~~~~~~~~~~~~~~^^^^^^^^^
  File "C:\Users\Arulraj\AppData\Roaming\Python\Python313\site-packages\django\template\base.py", line 966, in render_annotated
    return self.render(context)
           ~~~~~~~~~~~^^^^^^^^^
  File "C:\Users\Arulraj\AppData\Roaming\Python\Python313\site-packages\django\template\loader_tags.py", line 157, in render
    return compiled_parent._render(context)
           ~~~~~~~~~~~~~~~~~~~~~~~^^^^^^^^^
  File "C:\Users\Arulraj\AppData\Roaming\Python\Python313\site-packages\django\template\base.py", line 167, in _render
    return self.nodelist.render(context)
           ~~~~~~~~~~~~~~~~~~~~^^^^^^^^^
  File "C:\Users\Arulraj\AppData\Roaming\Python\Python313\site-packages\django\template\base.py", line 1005, in render
    return SafeString("".join([node.render_annotated(context) for node in self]))
                               ~~~~~~~~~~~~~~~~~~~~~^^^^^^^^^
  File "C:\Users\Arulraj\AppData\Roaming\Python\Python313\site-packages\django\template\base.py", line 966, in render_annotated
    return self.render(context)
           ~~~~~~~~~~~^^^^^^^^^
  File "C:\Users\Arulraj\AppData\Roaming\Python\Python313\site-packages\django\template\loader_tags.py", line 157, in render
    return compiled_parent._render(context)
           ~~~~~~~~~~~~~~~~~~~~~~~^^^^^^^^^
  File "C:\Users\Arulraj\AppData\Roaming\Python\Python313\site-packages\django\template\base.py", line 167, in _render
    return self.nodelist.render(context)
           ~~~~~~~~~~~~~~~~~~~~^^^^^^^^^
  File "C:\Users\Arulraj\AppData\Roaming\Python\Python313\site-packages\django\template\base.py", line 1005, in render
    return SafeString("".join([node.render_annotated(context) for node in self]))
                               ~~~~~~~~~~~~~~~~~~~~~^^^^^^^^^
  File "C:\Users\Arulraj\AppData\Roaming\Python\Python313\site-packages\django\template\base.py", line 966, in render_annotated
    return self.render(context)
           ~~~~~~~~~~~^^^^^^^^^
  File "C:\Users\Arulraj\AppData\Roaming\Python\Python313\site-packages\django\template\defaulttags.py", line 321, in render
    return nodelist.render(context)
           ~~~~~~~~~~~~~~~^^^^^^^^^
  File "C:\Users\Arulraj\AppData\Roaming\Python\Python313\site-packages\django\template\base.py", line 1005, in render
    return SafeString("".join([node.render_annotated(context) for node in self]))
                               ~~~~~~~~~~~~~~~~~~~~~^^^^^^^^^
  File "C:\Users\Arulraj\AppData\Roaming\Python\Python313\site-packages\django\template\base.py", line 966, in render_annotated
    return self.render(context)
           ~~~~~~~~~~~^^^^^^^^^
  File "C:\Users\Arulraj\AppData\Roaming\Python\Python313\site-packages\django\template\loader_tags.py", line 63, in render
    result = block.nodelist.render(context)
  File "C:\Users\Arulraj\AppData\Roaming\Python\Python313\site-packages\django\template\base.py", line 1005, in render
    return SafeString("".join([node.render_annotated(context) for node in self]))
                               ~~~~~~~~~~~~~~~~~~~~~^^^^^^^^^
  File "C:\Users\Arulraj\AppData\Roaming\Python\Python313\site-packages\django\template\base.py", line 966, in render_annotated
    return self.render(context)
           ~~~~~~~~~~~^^^^^^^^^
  File "C:\Users\Arulraj\AppData\Roaming\Python\Python313\site-packages\django\template\loader_tags.py", line 63, in render
    result = block.nodelist.render(context)
  File "C:\Users\Arulraj\AppData\Roaming\Python\Python313\site-packages\django\template\base.py", line 1005, in render
    return SafeString("".join([node.render_annotated(context) for node in self]))
                               ~~~~~~~~~~~~~~~~~~~~~^^^^^^^^^
  File "C:\Users\Arulraj\AppData\Roaming\Python\Python313\site-packages\django\template\base.py", line 966, in render_annotated
    return self.render(context)
           ~~~~~~~~~~~^^^^^^^^^
  File "C:\Users\Arulraj\AppData\Roaming\Python\Python313\site-packages\django\template\loader_tags.py", line 197, in render
    template = context.template.engine.select_template(template_name)
  File "C:\Users\Arulraj\AppData\Roaming\Python\Python313\site-packages\django\template\engine.py", line 212, in select_template
    raise TemplateDoesNotExist(", ".join(not_found))
django.template.exceptions.TemplateDoesNotExist: admin/includes/nav-global.html

The above exception was the direct cause of the following exception:

Traceback (most recent call last):
  File "C:\Users\Arulraj\AppData\Roaming\Python\Python313\site-packages\django\core\handlers\exception.py", line 55, in inner
    response = get_response(request)
  File "C:\Users\Arulraj\AppData\Roaming\Python\Python313\site-packages\django\core\handlers\base.py", line 197, in _get_response
    response = wrapped_callback(request, *callback_args, **callback_kwargs)
  File "C:\Users\Arulraj\AppData\Roaming\Python\Python313\site-packages\django\contrib\auth\decorators.py", line 23, in _wrapper_view
    return view_func(request, *args, **kwargs)
  File "C:\xampp\htdocs\skyplay_api_hub\wallet\views.py", line 33, in wallet_view
    return render(request, 'wallet/wallet.html', {'wallet': wallet, 'razorpay_key': RAZORPAY_KEY_ID, 'user_id': user_id ,  'transactions': transactions})
  File "C:\Users\Arulraj\AppData\Roaming\Python\Python313\site-packages\django\shortcuts.py", line 24, in render
    content = loader.render_to_string(template_name, context, request, using=using)
  File "C:\Users\Arulraj\AppData\Roaming\Python\Python313\site-packages\django\template\loader.py", line 62, in render_to_string
    return template.render(context, request)
           ~~~~~~~~~~~~~~~^^^^^^^^^^^^^^^^^^
  File "C:\Users\Arulraj\AppData\Roaming\Python\Python313\site-packages\django\template\backends\django.py", line 63, in render
    reraise(exc, self.backend)
    ~~~~~~~^^^^^^^^^^^^^^^^^^^
  File "C:\Users\Arulraj\AppData\Roaming\Python\Python313\site-packages\django\template\backends\django.py", line 84, in reraise
    raise new from exc
django.template.exceptions.TemplateDoesNotExist: admin/includes/nav-global.html
"GET /wallet/ HTTP/1.1" 500 246947
Internal Server Error: /wallet/
Traceback (most recent call last):
  File "C:\Users\Arulraj\AppData\Roaming\Python\Python313\site-packages\django\template\backends\django.py", line 61, in render
    return self.template.render(context)
           ~~~~~~~~~~~~~~~~~~~~^^^^^^^^^
  File "C:\Users\Arulraj\AppData\Roaming\Python\Python313\site-packages\django\template\base.py", line 175, in render
    return self._render(context)
           ~~~~~~~~~~~~^^^^^^^^^
  File "C:\Users\Arulraj\AppData\Roaming\Python\Python313\site-packages\django\template\base.py", line 167, in _render
    return self.nodelist.render(context)
           ~~~~~~~~~~~~~~~~~~~~^^^^^^^^^
  File "C:\Users\Arulraj\AppData\Roaming\Python\Python313\site-packages\django\template\base.py", line 1005, in render
    return SafeString("".join([node.render_annotated(context) for node in self]))
                               ~~~~~~~~~~~~~~~~~~~~~^^^^^^^^^
  File "C:\Users\Arulraj\AppData\Roaming\Python\Python313\site-packages\django\template\base.py", line 966, in render_annotated
    return self.render(context)
           ~~~~~~~~~~~^^^^^^^^^
  File "C:\Users\Arulraj\AppData\Roaming\Python\Python313\site-packages\django\template\loader_tags.py", line 157, in render
    return compiled_parent._render(context)
           ~~~~~~~~~~~~~~~~~~~~~~~^^^^^^^^^
  File "C:\Users\Arulraj\AppData\Roaming\Python\Python313\site-packages\django\template\base.py", line 167, in _render
    return self.nodelist.render(context)
           ~~~~~~~~~~~~~~~~~~~~^^^^^^^^^
  File "C:\Users\Arulraj\AppData\Roaming\Python\Python313\site-packages\django\template\base.py", line 1005, in render
    return SafeString("".join([node.render_annotated(context) for node in self]))
                               ~~~~~~~~~~~~~~~~~~~~~^^^^^^^^^
  File "C:\Users\Arulraj\AppData\Roaming\Python\Python313\site-packages\django\template\base.py", line 966, in render_annotated
    return self.render(context)
           ~~~~~~~~~~~^^^^^^^^^
  File "C:\Users\Arulraj\AppData\Roaming\Python\Python313\site-packages\django\template\loader_tags.py", line 157, in render
    return compiled_parent._render(context)
           ~~~~~~~~~~~~~~~~~~~~~~~^^^^^^^^^
  File "C:\Users\Arulraj\AppData\Roaming\Python\Python313\site-packages\django\template\base.py", line 167, in _render
    return self.nodelist.render(context)
           ~~~~~~~~~~~~~~~~~~~~^^^^^^^^^
  File "C:\Users\Arulraj\AppData\Roaming\Python\Python313\site-packages\django\template\base.py", line 1005, in render
    return SafeString("".join([node.render_annotated(context) for node in self]))
                               ~~~~~~~~~~~~~~~~~~~~~^^^^^^^^^
  File "C:\Users\Arulraj\AppData\Roaming\Python\Python313\site-packages\django\template\base.py", line 966, in render_annotated
    return self.render(context)
           ~~~~~~~~~~~^^^^^^^^^
  File "C:\Users\Arulraj\AppData\Roaming\Python\Python313\site-packages\django\template\defaulttags.py", line 321, in render
    return nodelist.render(context)
           ~~~~~~~~~~~~~~~^^^^^^^^^
  File "C:\Users\Arulraj\AppData\Roaming\Python\Python313\site-packages\django\template\base.py", line 1005, in render
    return SafeString("".join([node.render_annotated(context) for node in self]))
                               ~~~~~~~~~~~~~~~~~~~~~^^^^^^^^^
  File "C:\Users\Arulraj\AppData\Roaming\Python\Python313\site-packages\django\template\base.py", line 966, in render_annotated
    return self.render(context)
           ~~~~~~~~~~~^^^^^^^^^
  File "C:\Users\Arulraj\AppData\Roaming\Python\Python313\site-packages\django\template\loader_tags.py", line 63, in render
    result = block.nodelist.render(context)
  File "C:\Users\Arulraj\AppData\Roaming\Python\Python313\site-packages\django\template\base.py", line 1005, in render
    return SafeString("".join([node.render_annotated(context) for node in self]))
                               ~~~~~~~~~~~~~~~~~~~~~^^^^^^^^^
  File "C:\Users\Arulraj\AppData\Roaming\Python\Python313\site-packages\django\template\base.py", line 966, in render_annotated
    return self.render(context)
           ~~~~~~~~~~~^^^^^^^^^
  File "C:\Users\Arulraj\AppData\Roaming\Python\Python313\site-packages\django\template\loader_tags.py", line 63, in render
    result = block.nodelist.render(context)
  File "C:\Users\Arulraj\AppData\Roaming\Python\Python313\site-packages\django\template\base.py", line 1005, in render
    return SafeString("".join([node.render_annotated(context) for node in self]))
                               ~~~~~~~~~~~~~~~~~~~~~^^^^^^^^^
  File "C:\Users\Arulraj\AppData\Roaming\Python\Python313\site-packages\django\template\base.py", line 966, in render_annotated
    return self.render(context)
           ~~~~~~~~~~~^^^^^^^^^
  File "C:\Users\Arulraj\AppData\Roaming\Python\Python313\site-packages\django\template\loader_tags.py", line 197, in render
    template = context.template.engine.select_template(template_name)
  File "C:\Users\Arulraj\AppData\Roaming\Python\Python313\site-packages\django\template\engine.py", line 212, in select_template
    raise TemplateDoesNotExist(", ".join(not_found))
django.template.exceptions.TemplateDoesNotExist: admin/includes/nav-global.html

The above exception was the direct cause of the following exception:

Traceback (most recent call last):
  File "C:\Users\Arulraj\AppData\Roaming\Python\Python313\site-packages\django\core\handlers\exception.py", line 55, in inner
    response = get_response(request)
  File "C:\Users\Arulraj\AppData\Roaming\Python\Python313\site-packages\django\core\handlers\base.py", line 197, in _get_response
    response = wrapped_callback(request, *callback_args, **callback_kwargs)
  File "C:\Users\Arulraj\AppData\Roaming\Python\Python313\site-packages\django\contrib\auth\decorators.py", line 23, in _wrapper_view
    return view_func(request, *args, **kwargs)
  File "C:\xampp\htdocs\skyplay_api_hub\wallet\views.py", line 33, in wallet_view
    return render(request, 'wallet/wallet.html', {'wallet': wallet, 'razorpay_key': RAZORPAY_KEY_ID, 'user_id': user_id ,  'transactions': transactions})
  File "C:\Users\Arulraj\AppData\Roaming\Python\Python313\site-packages\django\shortcuts.py", line 24, in render
    content = loader.render_to_string(template_name, context, request, using=using)
  File "C:\Users\Arulraj\AppData\Roaming\Python\Python313\site-packages\django\template\loader.py", line 62, in render_to_string
    return template.render(context, request)
           ~~~~~~~~~~~~~~~^^^^^^^^^^^^^^^^^^
  File "C:\Users\Arulraj\AppData\Roaming\Python\Python313\site-packages\django\template\backends\django.py", line 63, in render
    reraise(exc, self.backend)
    ~~~~~~~^^^^^^^^^^^^^^^^^^^
  File "C:\Users\Arulraj\AppData\Roaming\Python\Python313\site-packages\django\template\backends\django.py", line 84, in reraise
    raise new from exc
django.template.exceptions.TemplateDoesNotExist: admin/includes/nav-global.html
"GET /wallet/ HTTP/1.1" 500 246947
Internal Server Error: /wallet/
Traceback (most recent call last):
  File "C:\Users\Arulraj\AppData\Roaming\Python\Python313\site-packages\django\template\backends\django.py", line 61, in render
    return self.template.render(context)
           ~~~~~~~~~~~~~~~~~~~~^^^^^^^^^
  File "C:\Users\Arulraj\AppData\Roaming\Python\Python313\site-packages\django\template\base.py", line 175, in render
    return self._render(context)
           ~~~~~~~~~~~~^^^^^^^^^
  File "C:\Users\Arulraj\AppData\Roaming\Python\Python313\site-packages\django\template\base.py", line 167, in _render
    return self.nodelist.render(context)
           ~~~~~~~~~~~~~~~~~~~~^^^^^^^^^
  File "C:\Users\Arulraj\AppData\Roaming\Python\Python313\site-packages\django\template\base.py", line 1005, in render
    return SafeString("".join([node.render_annotated(context) for node in self]))
                               ~~~~~~~~~~~~~~~~~~~~~^^^^^^^^^
  File "C:\Users\Arulraj\AppData\Roaming\Python\Python313\site-packages\django\template\base.py", line 966, in render_annotated
    return self.render(context)
           ~~~~~~~~~~~^^^^^^^^^
  File "C:\Users\Arulraj\AppData\Roaming\Python\Python313\site-packages\django\template\loader_tags.py", line 157, in render
    return compiled_parent._render(context)
           ~~~~~~~~~~~~~~~~~~~~~~~^^^^^^^^^
  File "C:\Users\Arulraj\AppData\Roaming\Python\Python313\site-packages\django\template\base.py", line 167, in _render
    return self.nodelist.render(context)
           ~~~~~~~~~~~~~~~~~~~~^^^^^^^^^
  File "C:\Users\Arulraj\AppData\Roaming\Python\Python313\site-packages\django\template\base.py", line 1005, in render
    return SafeString("".join([node.render_annotated(context) for node in self]))
                               ~~~~~~~~~~~~~~~~~~~~~^^^^^^^^^
  File "C:\Users\Arulraj\AppData\Roaming\Python\Python313\site-packages\django\template\base.py", line 966, in render_annotated
    return self.render(context)
           ~~~~~~~~~~~^^^^^^^^^
  File "C:\Users\Arulraj\AppData\Roaming\Python\Python313\site-packages\django\template\loader_tags.py", line 157, in render
    return compiled_parent._render(context)
           ~~~~~~~~~~~~~~~~~~~~~~~^^^^^^^^^
  File "C:\Users\Arulraj\AppData\Roaming\Python\Python313\site-packages\django\template\base.py", line 167, in _render
    return self.nodelist.render(context)
           ~~~~~~~~~~~~~~~~~~~~^^^^^^^^^
  File "C:\Users\Arulraj\AppData\Roaming\Python\Python313\site-packages\django\template\base.py", line 1005, in render
    return SafeString("".join([node.render_annotated(context) for node in self]))
                               ~~~~~~~~~~~~~~~~~~~~~^^^^^^^^^
  File "C:\Users\Arulraj\AppData\Roaming\Python\Python313\site-packages\django\template\base.py", line 966, in render_annotated
    return self.render(context)
           ~~~~~~~~~~~^^^^^^^^^
  File "C:\Users\Arulraj\AppData\Roaming\Python\Python313\site-packages\django\template\defaulttags.py", line 321, in render
    return nodelist.render(context)
           ~~~~~~~~~~~~~~~^^^^^^^^^
  File "C:\Users\Arulraj\AppData\Roaming\Python\Python313\site-packages\django\template\base.py", line 1005, in render
    return SafeString("".join([node.render_annotated(context) for node in self]))
                               ~~~~~~~~~~~~~~~~~~~~~^^^^^^^^^
  File "C:\Users\Arulraj\AppData\Roaming\Python\Python313\site-packages\django\template\base.py", line 966, in render_annotated
    return self.render(context)
           ~~~~~~~~~~~^^^^^^^^^
  File "C:\Users\Arulraj\AppData\Roaming\Python\Python313\site-packages\django\template\loader_tags.py", line 63, in render
    result = block.nodelist.render(context)
  File "C:\Users\Arulraj\AppData\Roaming\Python\Python313\site-packages\django\template\base.py", line 1005, in render
    return SafeString("".join([node.render_annotated(context) for node in self]))
                               ~~~~~~~~~~~~~~~~~~~~~^^^^^^^^^
  File "C:\Users\Arulraj\AppData\Roaming\Python\Python313\site-packages\django\template\base.py", line 966, in render_annotated
    return self.render(context)
           ~~~~~~~~~~~^^^^^^^^^
  File "C:\Users\Arulraj\AppData\Roaming\Python\Python313\site-packages\django\template\loader_tags.py", line 63, in render
    result = block.nodelist.render(context)
  File "C:\Users\Arulraj\AppData\Roaming\Python\Python313\site-packages\django\template\base.py", line 1005, in render
    return SafeString("".join([node.render_annotated(context) for node in self]))
                               ~~~~~~~~~~~~~~~~~~~~~^^^^^^^^^
  File "C:\Users\Arulraj\AppData\Roaming\Python\Python313\site-packages\django\template\base.py", line 966, in render_annotated
    return self.render(context)
           ~~~~~~~~~~~^^^^^^^^^
  File "C:\Users\Arulraj\AppData\Roaming\Python\Python313\site-packages\django\template\loader_tags.py", line 197, in render
    template = context.template.engine.select_template(template_name)
  File "C:\Users\Arulraj\AppData\Roaming\Python\Python313\site-packages\django\template\engine.py", line 212, in select_template
    raise TemplateDoesNotExist(", ".join(not_found))
django.template.exceptions.TemplateDoesNotExist: admin/includes/nav-global.html

The above exception was the direct cause of the following exception:

Traceback (most recent call last):
  File "C:\Users\Arulraj\AppData\Roaming\Python\Python313\site-packages\django\core\handlers\exception.py", line 55, in inner
    response = get_response(request)
  File "C:\Users\Arulraj\AppData\Roaming\Python\Python313\site-packages\django\core\handlers\base.py", line 197, in _get_response
    response = wrapped_callback(request, *callback_args, **callback_kwargs)
  File "C:\Users\Arulraj\AppData\Roaming\Python\Python313\site-packages\django\contrib\auth\decorators.py", line 23, in _wrapper_view
    return view_func(request, *args, **kwargs)
  File "C:\xampp\htdocs\skyplay_api_hub\wallet\views.py", line 33, in wallet_view
    return render(request, 'wallet/wallet.html', {'wallet': wallet, 'razorpay_key': RAZORPAY_KEY_ID, 'user_id': user_id ,  'transactions': transactions})
  File "C:\Users\Arulraj\AppData\Roaming\Python\Python313\site-packages\django\shortcuts.py", line 24, in render
    content = loader.render_to_string(template_name, context, request, using=using)
  File "C:\Users\Arulraj\AppData\Roaming\Python\Python313\site-packages\django\template\loader.py", line 62, in render_to_string
    return template.render(context, request)
           ~~~~~~~~~~~~~~~^^^^^^^^^^^^^^^^^^
  File "C:\Users\Arulraj\AppData\Roaming\Python\Python313\site-packages\django\template\backends\django.py", line 63, in render
    reraise(exc, self.backend)
    ~~~~~~~^^^^^^^^^^^^^^^^^^^
  File "C:\Users\Arulraj\AppData\Roaming\Python\Python313\site-packages\django\template\backends\django.py", line 84, in reraise
    raise new from exc
django.template.exceptions.TemplateDoesNotExist: admin/includes/nav-global.html
"GET /wallet/ HTTP/1.1" 500 246947
Internal Server Error: /wallet/
Traceback (most recent call last):
  File "C:\Users\Arulraj\AppData\Roaming\Python\Python313\site-packages\django\template\backends\django.py", line 61, in render
    return self.template.render(context)
           ~~~~~~~~~~~~~~~~~~~~^^^^^^^^^
  File "C:\Users\Arulraj\AppData\Roaming\Python\Python313\site-packages\django\template\base.py", line 175, in render
    return self._render(context)
           ~~~~~~~~~~~~^^^^^^^^^
  File "C:\Users\Arulraj\AppData\Roaming\Python\Python313\site-packages\django\template\base.py", line 167, in _render
    return self.nodelist.render(context)
           ~~~~~~~~~~~~~~~~~~~~^^^^^^^^^
  File "C:\Users\Arulraj\AppData\Roaming\Python\Python313\site-packages\django\template\base.py", line 1005, in render
    return SafeString("".join([node.render_annotated(context) for node in self]))
                               ~~~~~~~~~~~~~~~~~~~~~^^^^^^^^^
  File "C:\Users\Arulraj\AppData\Roaming\Python\Python313\site-packages\django\template\base.py", line 966, in render_annotated
    return self.render(context)
           ~~~~~~~~~~~^^^^^^^^^
  File "C:\Users\Arulraj\AppData\Roaming\Python\Python313\site-packages\django\template\loader_tags.py", line 157, in render
    return compiled_parent._render(context)
           ~~~~~~~~~~~~~~~~~~~~~~~^^^^^^^^^
  File "C:\Users\Arulraj\AppData\Roaming\Python\Python313\site-packages\django\template\base.py", line 167, in _render
    return self.nodelist.render(context)
           ~~~~~~~~~~~~~~~~~~~~^^^^^^^^^
  File "C:\Users\Arulraj\AppData\Roaming\Python\Python313\site-packages\django\template\base.py", line 1005, in render
    return SafeString("".join([node.render_annotated(context) for node in self]))
                               ~~~~~~~~~~~~~~~~~~~~~^^^^^^^^^
  File "C:\Users\Arulraj\AppData\Roaming\Python\Python313\site-packages\django\template\base.py", line 966, in render_annotated
    return self.render(context)
           ~~~~~~~~~~~^^^^^^^^^
  File "C:\Users\Arulraj\AppData\Roaming\Python\Python313\site-packages\django\template\loader_tags.py", line 157, in render
    return compiled_parent._render(context)
           ~~~~~~~~~~~~~~~~~~~~~~~^^^^^^^^^
  File "C:\Users\Arulraj\AppData\Roaming\Python\Python313\site-packages\django\template\base.py", line 167, in _render
    return self.nodelist.render(context)
           ~~~~~~~~~~~~~~~~~~~~^^^^^^^^^
  File "C:\Users\Arulraj\AppData\Roaming\Python\Python313\site-packages\django\template\base.py", line 1005, in render
    return SafeString("".join([node.render_annotated(context) for node in self]))
                               ~~~~~~~~~~~~~~~~~~~~~^^^^^^^^^
  File "C:\Users\Arulraj\AppData\Roaming\Python\Python313\site-packages\django\template\base.py", line 966, in render_annotated
    return self.render(context)
           ~~~~~~~~~~~^^^^^^^^^
  File "C:\Users\Arulraj\AppData\Roaming\Python\Python313\site-packages\django\template\defaulttags.py", line 321, in render
    return nodelist.render(context)
           ~~~~~~~~~~~~~~~^^^^^^^^^
  File "C:\Users\Arulraj\AppData\Roaming\Python\Python313\site-packages\django\template\base.py", line 1005, in render
    return SafeString("".join([node.render_annotated(context) for node in self]))
                               ~~~~~~~~~~~~~~~~~~~~~^^^^^^^^^
  File "C:\Users\Arulraj\AppData\Roaming\Python\Python313\site-packages\django\template\base.py", line 966, in render_annotated
    return self.render(context)
           ~~~~~~~~~~~^^^^^^^^^
  File "C:\Users\Arulraj\AppData\Roaming\Python\Python313\site-packages\django\template\loader_tags.py", line 63, in render
    result = block.nodelist.render(context)
  File "C:\Users\Arulraj\AppData\Roaming\Python\Python313\site-packages\django\template\base.py", line 1005, in render
    return SafeString("".join([node.render_annotated(context) for node in self]))
                               ~~~~~~~~~~~~~~~~~~~~~^^^^^^^^^
  File "C:\Users\Arulraj\AppData\Roaming\Python\Python313\site-packages\django\template\base.py", line 966, in render_annotated
    return self.render(context)
           ~~~~~~~~~~~^^^^^^^^^
  File "C:\Users\Arulraj\AppData\Roaming\Python\Python313\site-packages\django\template\loader_tags.py", line 63, in render
    result = block.nodelist.render(context)
  File "C:\Users\Arulraj\AppData\Roaming\Python\Python313\site-packages\django\template\base.py", line 1005, in render
    return SafeString("".join([node.render_annotated(context) for node in self]))
                               ~~~~~~~~~~~~~~~~~~~~~^^^^^^^^^
  File "C:\Users\Arulraj\AppData\Roaming\Python\Python313\site-packages\django\template\base.py", line 966, in render_annotated
    return self.render(context)
           ~~~~~~~~~~~^^^^^^^^^
  File "C:\Users\Arulraj\AppData\Roaming\Python\Python313\site-packages\django\template\loader_tags.py", line 197, in render
    template = context.template.engine.select_template(template_name)
  File "C:\Users\Arulraj\AppData\Roaming\Python\Python313\site-packages\django\template\engine.py", line 212, in select_template
    raise TemplateDoesNotExist(", ".join(not_found))
django.template.exceptions.TemplateDoesNotExist: admin/includes/nav-global.html

The above exception was the direct cause of the following exception:

Traceback (most recent call last):
  File "C:\Users\Arulraj\AppData\Roaming\Python\Python313\site-packages\django\core\handlers\exception.py", line 55, in inner
    response = get_response(request)
  File "C:\Users\Arulraj\AppData\Roaming\Python\Python313\site-packages\django\core\handlers\base.py", line 197, in _get_response
    response = wrapped_callback(request, *callback_args, **callback_kwargs)
  File "C:\Users\Arulraj\AppData\Roaming\Python\Python313\site-packages\django\contrib\auth\decorators.py", line 23, in _wrapper_view
    return view_func(request, *args, **kwargs)
  File "C:\xampp\htdocs\skyplay_api_hub\wallet\views.py", line 33, in wallet_view
    return render(request, 'wallet/wallet.html', {'wallet': wallet, 'razorpay_key': RAZORPAY_KEY_ID, 'user_id': user_id ,  'transactions': transactions})
  File "C:\Users\Arulraj\AppData\Roaming\Python\Python313\site-packages\django\shortcuts.py", line 24, in render
    content = loader.render_to_string(template_name, context, request, using=using)
  File "C:\Users\Arulraj\AppData\Roaming\Python\Python313\site-packages\django\template\loader.py", line 62, in render_to_string
    return template.render(context, request)
           ~~~~~~~~~~~~~~~^^^^^^^^^^^^^^^^^^
  File "C:\Users\Arulraj\AppData\Roaming\Python\Python313\site-packages\django\template\backends\django.py", line 63, in render
    reraise(exc, self.backend)
    ~~~~~~~^^^^^^^^^^^^^^^^^^^
  File "C:\Users\Arulraj\AppData\Roaming\Python\Python313\site-packages\django\template\backends\django.py", line 84, in reraise
    raise new from exc
django.template.exceptions.TemplateDoesNotExist: admin/includes/nav-global.html
"GET /wallet/ HTTP/1.1" 500 238844
Internal Server Error: /wallet/
Traceback (most recent call last):
  File "C:\Users\Arulraj\AppData\Roaming\Python\Python313\site-packages\django\template\backends\django.py", line 61, in render
    return self.template.render(context)
           ~~~~~~~~~~~~~~~~~~~~^^^^^^^^^
  File "C:\Users\Arulraj\AppData\Roaming\Python\Python313\site-packages\django\template\base.py", line 175, in render
    return self._render(context)
           ~~~~~~~~~~~~^^^^^^^^^
  File "C:\Users\Arulraj\AppData\Roaming\Python\Python313\site-packages\django\template\base.py", line 167, in _render
    return self.nodelist.render(context)
           ~~~~~~~~~~~~~~~~~~~~^^^^^^^^^
  File "C:\Users\Arulraj\AppData\Roaming\Python\Python313\site-packages\django\template\base.py", line 1005, in render
    return SafeString("".join([node.render_annotated(context) for node in self]))
                               ~~~~~~~~~~~~~~~~~~~~~^^^^^^^^^
  File "C:\Users\Arulraj\AppData\Roaming\Python\Python313\site-packages\django\template\base.py", line 966, in render_annotated
    return self.render(context)
           ~~~~~~~~~~~^^^^^^^^^
  File "C:\Users\Arulraj\AppData\Roaming\Python\Python313\site-packages\django\template\loader_tags.py", line 157, in render
    return compiled_parent._render(context)
           ~~~~~~~~~~~~~~~~~~~~~~~^^^^^^^^^
  File "C:\Users\Arulraj\AppData\Roaming\Python\Python313\site-packages\django\template\base.py", line 167, in _render
    return self.nodelist.render(context)
           ~~~~~~~~~~~~~~~~~~~~^^^^^^^^^
  File "C:\Users\Arulraj\AppData\Roaming\Python\Python313\site-packages\django\template\base.py", line 1005, in render
    return SafeString("".join([node.render_annotated(context) for node in self]))
                               ~~~~~~~~~~~~~~~~~~~~~^^^^^^^^^
  File "C:\Users\Arulraj\AppData\Roaming\Python\Python313\site-packages\django\template\base.py", line 966, in render_annotated
    return self.render(context)
           ~~~~~~~~~~~^^^^^^^^^
  File "C:\Users\Arulraj\AppData\Roaming\Python\Python313\site-packages\django\template\loader_tags.py", line 157, in render
    return compiled_parent._render(context)
           ~~~~~~~~~~~~~~~~~~~~~~~^^^^^^^^^
  File "C:\Users\Arulraj\AppData\Roaming\Python\Python313\site-packages\django\template\base.py", line 167, in _render
    return self.nodelist.render(context)
           ~~~~~~~~~~~~~~~~~~~~^^^^^^^^^
  File "C:\Users\Arulraj\AppData\Roaming\Python\Python313\site-packages\django\template\base.py", line 1005, in render
    return SafeString("".join([node.render_annotated(context) for node in self]))
                               ~~~~~~~~~~~~~~~~~~~~~^^^^^^^^^
  File "C:\Users\Arulraj\AppData\Roaming\Python\Python313\site-packages\django\template\base.py", line 966, in render_annotated
    return self.render(context)
           ~~~~~~~~~~~^^^^^^^^^
  File "C:\Users\Arulraj\AppData\Roaming\Python\Python313\site-packages\django\template\defaulttags.py", line 321, in render
    return nodelist.render(context)
           ~~~~~~~~~~~~~~~^^^^^^^^^
  File "C:\Users\Arulraj\AppData\Roaming\Python\Python313\site-packages\django\template\base.py", line 1005, in render
    return SafeString("".join([node.render_annotated(context) for node in self]))
                               ~~~~~~~~~~~~~~~~~~~~~^^^^^^^^^
  File "C:\Users\Arulraj\AppData\Roaming\Python\Python313\site-packages\django\template\base.py", line 966, in render_annotated
    return self.render(context)
           ~~~~~~~~~~~^^^^^^^^^
  File "C:\Users\Arulraj\AppData\Roaming\Python\Python313\site-packages\django\template\loader_tags.py", line 63, in render
    result = block.nodelist.render(context)
  File "C:\Users\Arulraj\AppData\Roaming\Python\Python313\site-packages\django\template\base.py", line 1005, in render
    return SafeString("".join([node.render_annotated(context) for node in self]))
                               ~~~~~~~~~~~~~~~~~~~~~^^^^^^^^^
  File "C:\Users\Arulraj\AppData\Roaming\Python\Python313\site-packages\django\template\base.py", line 966, in render_annotated
    return self.render(context)
           ~~~~~~~~~~~^^^^^^^^^
  File "C:\Users\Arulraj\AppData\Roaming\Python\Python313\site-packages\django\template\loader_tags.py", line 63, in render
    result = block.nodelist.render(context)
  File "C:\Users\Arulraj\AppData\Roaming\Python\Python313\site-packages\django\template\base.py", line 1005, in render
    return SafeString("".join([node.render_annotated(context) for node in self]))
                               ~~~~~~~~~~~~~~~~~~~~~^^^^^^^^^
  File "C:\Users\Arulraj\AppData\Roaming\Python\Python313\site-packages\django\template\base.py", line 966, in render_annotated
    return self.render(context)
           ~~~~~~~~~~~^^^^^^^^^
  File "C:\Users\Arulraj\AppData\Roaming\Python\Python313\site-packages\django\template\loader_tags.py", line 197, in render
    template = context.template.engine.select_template(template_name)
  File "C:\Users\Arulraj\AppData\Roaming\Python\Python313\site-packages\django\template\engine.py", line 212, in select_template
    raise TemplateDoesNotExist(", ".join(not_found))
django.template.exceptions.TemplateDoesNotExist: admin/includes/nav-global.html

The above exception was the direct cause of the following exception:

Traceback (most recent call last):
  File "C:\Users\Arulraj\AppData\Roaming\Python\Python313\site-packages\django\core\handlers\exception.py", line 55, in inner
    response = get_response(request)
  File "C:\Users\Arulraj\AppData\Roaming\Python\Python313\site-packages\django\core\handlers\base.py", line 197, in _get_response
    response = wrapped_callback(request, *callback_args, **callback_kwargs)
  File "C:\Users\Arulraj\AppData\Roaming\Python\Python313\site-packages\django\contrib\auth\decorators.py", line 23, in _wrapper_view
    return view_func(request, *args, **kwargs)
  File "C:\xampp\htdocs\skyplay_api_hub\wallet\views.py", line 33, in wallet_view
    return render(request, 'wallet/wallet.html', {'wallet': wallet, 'razorpay_key': RAZORPAY_KEY_ID, 'user_id': user_id ,  'transactions': transactions})
  File "C:\Users\Arulraj\AppData\Roaming\Python\Python313\site-packages\django\shortcuts.py", line 24, in render
    content = loader.render_to_string(template_name, context, request, using=using)
  File "C:\Users\Arulraj\AppData\Roaming\Python\Python313\site-packages\django\template\loader.py", line 62, in render_to_string
    return template.render(context, request)
           ~~~~~~~~~~~~~~~^^^^^^^^^^^^^^^^^^
  File "C:\Users\Arulraj\AppData\Roaming\Python\Python313\site-packages\django\template\backends\django.py", line 63, in render
    reraise(exc, self.backend)
    ~~~~~~~^^^^^^^^^^^^^^^^^^^
  File "C:\Users\Arulraj\AppData\Roaming\Python\Python313\site-packages\django\template\backends\django.py", line 84, in reraise
    raise new from exc
django.template.exceptions.TemplateDoesNotExist: admin/includes/nav-global.html
"GET /wallet/ HTTP/1.1" 500 238844
Internal Server Error: /skyplay_api/set_subscribe_to_channel/2/2025-02-18/22/2/
"GET /skyplay_api/set_subscribe_to_channel/2/2025-02-18/22/2/ HTTP/1.1" 500 52
Internal Server Error: /skyplay_api/set_subscribe_to_channel/44/2025-02-10/4/44/
"GET /skyplay_api/set_subscribe_to_channel/44/2025-02-10/4/44/ HTTP/1.1" 500 52
Internal Server Error: /skyplay_api/set_subscribe_to_channel/2/2025-02-04/22/2/
"GET /skyplay_api/set_subscribe_to_channel/2/2025-02-04/22/2/ HTTP/1.1" 500 52
Internal Server Error: /skyplay_api/set_subscribe_to_channel/2/2025-02-04/22/2/
"GET /skyplay_api/set_subscribe_to_channel/2/2025-02-04/22/2/ HTTP/1.1" 500 52
Internal Server Error: /skyplay_api/set_subscribe_to_channel/2/2025-02-04/22/2/
"GET /skyplay_api/set_subscribe_to_channel/2/2025-02-04/22/2/ HTTP/1.1" 500 52
Internal Server Error: /skyplay_api/set_subscribe_to_channel/2/2025-02-10/22/2/
"GET /skyplay_api/set_subscribe_to_channel/2/2025-02-10/22/2/ HTTP/1.1" 500 52
Internal Server Error: /skyplay_api/set_subscribe_to_channel/1/2025-02-12/2/1/
Internal Server Error: /api/subscription/request-watchoplan/
Traceback (most recent call last):
  File "C:\Users\Arulraj\AppData\Roaming\Python\Python313\site-packages\django\core\handlers\exception.py", line 55, in inner
    response = get_response(request)
  File "C:\Users\Arulraj\AppData\Roaming\Python\Python313\site-packages\django\core\handlers\base.py", line 197, in _get_response
    response = wrapped_callback(request, *callback_args, **callback_kwargs)
  File "C:\Users\Arulraj\AppData\Roaming\Python\Python313\site-packages\django\views\decorators\csrf.py", line 56, in wrapper_view
    return view_func(*args, **kwargs)
  File "C:\Users\Arulraj\AppData\Roaming\Python\Python313\site-packages\django\views\generic\base.py", line 104, in view
    return self.dispatch(request, *args, **kwargs)
           ~~~~~~~~~~~~~^^^^^^^^^^^^^^^^^^^^^^^^^^
  File "C:\Users\Arulraj\AppData\Roaming\Python\Python313\site-packages\rest_framework\views.py", line 509, in dispatch
    response = self.handle_exception(exc)
  File "C:\Users\Arulraj\AppData\Roaming\Python\Python313\site-packages\rest_framework\views.py", line 469, in handle_exception
    self.raise_uncaught_exception(exc)
    ~~~~~~~~~~~~~~~~~~~~~~~~~~~~~^^^^^
  File "C:\Users\Arulraj\AppData\Roaming\Python\Python313\site-packages\rest_framework\views.py", line 480, in raise_uncaught_exception
    raise exc
  File "C:\Users\Arulraj\AppData\Roaming\Python\Python313\site-packages\rest_framework\views.py", line 506, in dispatch
    response = handler(request, *args, **kwargs)
  File "C:\Users\Arulraj\AppData\Roaming\Python\Python313\site-packages\rest_framework\decorators.py", line 50, in handler
    return func(*args, **kwargs)
  File "C:\xampp\htdocs\skyplay_api_hub\testapp\views.py", line 433, in subscription_request_watchoplan
    encrypted_request = encrypt_data(request_data)
  File "C:\xampp\htdocs\skyplay_api_hub\testapp\views.py", line 343, in encrypt_data
    json_data = json.dumps(data)
                ^^^^
NameError: name 'json' is not defined. Did you forget to import 'json'?
"POST /api/subscription/request-watchoplan/ HTTP/1.1" 500 18137
Internal Server Error: /api/subscription/request-watchoplan/
Traceback (most recent call last):
  File "C:\Users\Arulraj\AppData\Roaming\Python\Python313\site-packages\django\core\handlers\exception.py", line 55, in inner
    response = get_response(request)
  File "C:\Users\Arulraj\AppData\Roaming\Python\Python313\site-packages\django\core\handlers\base.py", line 197, in _get_response
    response = wrapped_callback(request, *callback_args, **callback_kwargs)
  File "C:\Users\Arulraj\AppData\Roaming\Python\Python313\site-packages\django\views\decorators\csrf.py", line 56, in wrapper_view
    return view_func(*args, **kwargs)
  File "C:\Users\Arulraj\AppData\Roaming\Python\Python313\site-packages\django\views\generic\base.py", line 104, in view
    return self.dispatch(request, *args, **kwargs)
           ~~~~~~~~~~~~~^^^^^^^^^^^^^^^^^^^^^^^^^^
  File "C:\Users\Arulraj\AppData\Roaming\Python\Python313\site-packages\rest_framework\views.py", line 509, in dispatch
    response = self.handle_exception(exc)
  File "C:\Users\Arulraj\AppData\Roaming\Python\Python313\site-packages\rest_framework\views.py", line 469, in handle_exception
    self.raise_uncaught_exception(exc)
    ~~~~~~~~~~~~~~~~~~~~~~~~~~~~~^^^^^
  File "C:\Users\Arulraj\AppData\Roaming\Python\Python313\site-packages\rest_framework\views.py", line 480, in raise_uncaught_exception
    raise exc
  File "C:\Users\Arulraj\AppData\Roaming\Python\Python313\site-packages\rest_framework\views.py", line 506, in dispatch
    response = handler(request, *args, **kwargs)
  File "C:\Users\Arulraj\AppData\Roaming\Python\Python313\site-packages\rest_framework\decorators.py", line 50, in handler
    return func(*args, **kwargs)
  File "C:\xampp\htdocs\skyplay_api_hub\testapp\views.py", line 458, in subscription_request_watchoplan
    encrypted_request = encrypt_data(request_data)
  File "C:\xampp\htdocs\skyplay_api_hub\testapp\views.py", line 423, in encrypt_data
    json_data = json.dumps(data)
                ^^^^
NameError: name 'json' is not defined. Did you forget to import 'json'?
"POST /api/subscription/request-watchoplan/ HTTP/1.1" 500 18145
Internal Server Error: /api/subscription/request-watchoplan/
Traceback (most recent call last):
  File "C:\Users\Arulraj\AppData\Roaming\Python\Python313\site-packages\django\core\handlers\exception.py", line 55, in inner
    response = get_response(request)
  File "C:\Users\Arulraj\AppData\Roaming\Python\Python313\site-packages\django\core\handlers\base.py", line 197, in _get_response
    response = wrapped_callback(request, *callback_args, **callback_kwargs)
  File "C:\Users\Arulraj\AppData\Roaming\Python\Python313\site-packages\django\views\decorators\csrf.py", line 56, in wrapper_view
    return view_func(*args, **kwargs)
  File "C:\Users\Arulraj\AppData\Roaming\Python\Python313\site-packages\django\views\generic\base.py", line 104, in view
    return self.dispatch(request, *args, **kwargs)
           ~~~~~~~~~~~~~^^^^^^^^^^^^^^^^^^^^^^^^^^
  File "C:\Users\Arulraj\AppData\Roaming\Python\Python313\site-packages\rest_framework\views.py", line 509, in dispatch
    response = self.handle_exception(exc)
  File "C:\Users\Arulraj\AppData\Roaming\Python\Python313\site-packages\rest_framework\views.py", line 469, in handle_exception
    self.raise_uncaught_exception(exc)
    ~~~~~~~~~~~~~~~~~~~~~~~~~~~~~^^^^^
  File "C:\Users\Arulraj\AppData\Roaming\Python\Python313\site-packages\rest_framework\views.py", line 480, in raise_uncaught_exception
    raise exc
  File "C:\Users\Arulraj\AppData\Roaming\Python\Python313\site-packages\rest_framework\views.py", line 506, in dispatch
    response = handler(request, *args, **kwargs)
  File "C:\Users\Arulraj\AppData\Roaming\Python\Python313\site-packages\rest_framework\decorators.py", line 50, in handler
    return func(*args, **kwargs)
  File "C:\xampp\htdocs\skyplay_api_hub\testapp\views.py", line 454, in subscription_request_watchoplan
    encrypted_request = encrypt_data(request_data)
  File "C:\xampp\htdocs\skyplay_api_hub\testapp\views.py", line 343, in encrypt_data
    json_data = json.dumps(data)
                ^^^^
NameError: name 'json' is not defined. Did you forget to import 'json'?
"POST /api/subscription/request-watchoplan/ HTTP/1.1" 500 18145
Internal Server Error: /api/subscription/request-watchoplan/
Traceback (most recent call last):
  File "C:\Users\Arulraj\AppData\Roaming\Python\Python313\site-packages\django\core\handlers\exception.py", line 55, in inner
    response = get_response(request)
  File "C:\Users\Arulraj\AppData\Roaming\Python\Python313\site-packages\django\core\handlers\base.py", line 197, in _get_response
    response = wrapped_callback(request, *callback_args, **callback_kwargs)
  File "C:\Users\Arulraj\AppData\Roaming\Python\Python313\site-packages\django\views\decorators\csrf.py", line 56, in wrapper_view
    return view_func(*args, **kwargs)
  File "C:\Users\Arulraj\AppData\Roaming\Python\Python313\site-packages\django\views\generic\base.py", line 104, in view
    return self.dispatch(request, *args, **kwargs)
           ~~~~~~~~~~~~~^^^^^^^^^^^^^^^^^^^^^^^^^^
  File "C:\Users\Arulraj\AppData\Roaming\Python\Python313\site-packages\rest_framework\views.py", line 509, in dispatch
    response = self.handle_exception(exc)
  File "C:\Users\Arulraj\AppData\Roaming\Python\Python313\site-packages\rest_framework\views.py", line 469, in handle_exception
    self.raise_uncaught_exception(exc)
    ~~~~~~~~~~~~~~~~~~~~~~~~~~~~~^^^^^
  File "C:\Users\Arulraj\AppData\Roaming\Python\Python313\site-packages\rest_framework\views.py", line 480, in raise_uncaught_exception
    raise exc
  File "C:\Users\Arulraj\AppData\Roaming\Python\Python313\site-packages\rest_framework\views.py", line 506, in dispatch
    response = handler(request, *args, **kwargs)
  File "C:\Users\Arulraj\AppData\Roaming\Python\Python313\site-packages\rest_framework\decorators.py", line 50, in handler
    return func(*args, **kwargs)
  File "C:\xampp\htdocs\skyplay_api_hub\testapp\views.py", line 457, in subscription_request_watchoplan
    encrypted_request = encrypt_data(request_data)
  File "C:\xampp\htdocs\skyplay_api_hub\testapp\views.py", line 422, in encrypt_data
    json_data = json.dumps(data)  # Ensure json is imported
                ^^^^
NameError: name 'json' is not defined. Did you forget to import 'json'?
"POST /api/subscription/request-watchoplan/ HTTP/1.1" 500 18172
